Workbook

Sheet CIF
C3: Origin Warehouse | N3: Inland Logistics | S3: Consolidation | X3: Outbound Logistics | AB3: Documentation | AH3: CIF | AN3: Cert Costs | AQ3: Terms Total
B4: Region | C4: Terms | D4: Receiving | E4: Load Out | F4: Compression | G4: Class | H4: Marking | I4: Storage | J4: Interest | K4: Origin Commission | L4: Total Equity | M4: Total Origin | N4: Flatbed | O4: Late Fee | P4: Transit Truck | R4: Total Inland | S4: Block Handling | T4: Storage | U4: Interest | W4: Total Consol | X4: Dray | Y4: Ocean | AA4: Total Out | AB4: Sight LC | AC4: Forwarding | AD4: Controlling | AE4: Insurance | AG4: Total Doc | AH4: Destination Comission | AI4: Cost of Funds | AJ4: Qclaim | AM4: Total CIF | AN4: USDA | AO4: ICE | AP4: Total CERT | AQ4: Cash | AR4: Equity
B5: WTX | D5: {=AVERAGE(_xlfn._xlws.FILTER(PTS!I:I, (PTS!$E:$E="WTX") * ISNUMBER(PTS!I:I)))} -> 93.277193 | E5: {=AVERAGE(_xlfn._xlws.FILTER(PTS!J:J, (PTS!$E:$E="WTX") * ISNUMBER(PTS!J:J)))} -> 124.68421 | F5: {=AVERAGE(_xlfn._xlws.FILTER(PTS!K:K, (PTS!$E:$E="WTX") * ISNUMBER(PTS!K:K)))} -> 203.04912 | G5: {=AVERAGE(_xlfn._xlws.FILTER(PTS!L:L, (PTS!$E:$E="WTX") * ISNUMBER(PTS!L:L)))} -> 0 | H5: {=AVERAGE(_xlfn._xlws.FILTER(PTS!M:M, (PTS!$E:$E="WTX") * ISNUMBER(PTS!M:M)))} -> 4.5263158 | I5: {=AVERAGE(_xlfn._xlws.FILTER(PTS!N:N, (PTS!$E:$E="WTX") * ISNUMBER(PTS!N:N)))} -> 54.473684 | J5: {=AVERAGE(_xlfn._xlws.FILTER(PTS!O:O, (PTS!$E:$E="WTX") * ISNUMBER(PTS!O:O)))} -> 37.916667 | K5: {=AVERAGE(_xlfn._xlws.FILTER(PTS!P:P, (PTS!$E:$E="WTX") * ISNUMBER(PTS!P:P)))} -> 0 | L5: {=AVERAGE(_xlfn._xlws.FILTER(PTS!Q:Q, (PTS!$E:$E="WTX") * ISNUMBER(PTS!Q:Q)))} -> 518.74259 | M5: {=AVERAGE(_xlfn._xlws.FILTER(PTS!R:R, (PTS!$E:$E="WTX") * ISNUMBER(PTS!R:R)))} -> 307.52024 | N5: {=AVERAGE(_xlfn._xlws.FILTER(PTS!S:S, (PTS!$E:$E="WTX") * ISNUMBER(PTS!S:S)))} -> 4.9122807 | O5: {=AVERAGE(_xlfn._xlws.FILTER(PTS!T:T, (PTS!$E:$E="WTX") * ISNUMBER(PTS!T:T)))} -> 1.1403509 | P5: {=AVERAGE(_xlfn._xlws.FILTER(PTS!U:U, (PTS!$E:$E="WTX") * ISNUMBER(PTS!U:U)))} -> 186.05615 | R5: {=AVERAGE(_xlfn._xlws.FILTER(PTS!W:W, (PTS!$E:$E="WTX") * ISNUMBER(PTS!W:W)))} -> 192.33066 | S5: {=AVERAGE(_xlfn._xlws.FILTER(PTS!X:X, (PTS!$E:$E="WTX") * ISNUMBER(PTS!X:X)))} -> 54 | T5: {=AVERAGE(_xlfn._xlws.FILTER(PTS!Y:Y, (PTS!$E:$E="WTX") * ISNUMBER(PTS!Y:Y)))} -> 50.4 | U5: {=AVERAGE(_xlfn._xlws.FILTER(PTS!Z:Z, (PTS!$E:$E="WTX") * ISNUMBER(PTS!Z:Z)))} -> 26.25 | W5: {=AVERAGE(_xlfn._xlws.FILTER(PTS!AB:AB, (PTS!$E:$E="WTX") * ISNUMBER(PTS!AB:AB)))} -> 130.65 | X5: {=AVERAGE(_xlfn._xlws.FILTER(PTS!AC:AC, (PTS!$E:$E="WTX") * ISNUMBER(PTS!AC:AC)))} -> 162.5 | Y5: {=AVERAGE(_xlfn._xlws.FILTER(PTS!AD:AD, (PTS!$E:$E="WTX") * ISNUMBER(PTS!AD:AD)))} -> 268.18182 | AA5: {=AVERAGE(_xlfn._xlws.FILTER(PTS!AF:AF, (PTS!$E:$E="WTX") * ISNUMBER(PTS!AF:AF)))} -> 430.68182 | AB5: {=AVERAGE(_xlfn._xlws.FILTER(PTS!AG:AG, (PTS!$E:$E="WTX") * ISNUMBER(PTS!AG:AG)))} -> 28.8143 | AC5: {=AVERAGE(_xlfn._xlws.FILTER(PTS!AH:AH, (PTS!$E:$E="WTX") * ISNUMBER(PTS!AH:AH)))} -> 6.9731405 | AD5: {=AVERAGE(_xlfn._xlws.FILTER(PTS!AI:AI, (PTS!$E:$E="WTX") * ISNUMBER(PTS!AI:AI)))} -> 12.587317 | AE5: {=AVERAGE(_xlfn._xlws.FILTER(PTS!AJ:AJ, (PTS!$E:$E="WTX") * ISNUMBER(PTS!AJ:AJ)))} -> 6.7352 | AG5: {=AVERAGE(_xlfn._xlws.FILTER(PTS!AL:AL, (PTS!$E:$E="WTX") * ISNUMBER(PTS!AL:AL)))} -> 55.109958 | AH5: {=AVERAGE(_xlfn._xlws.FILTER(PTS!AM:AM, (PTS!$E:$E="WTX") * ISNUMBER(PTS!AM:AM)))} -> 80 | AI5: {=AVERAGE(_xlfn._xlws.FILTER(PTS!AN:AN, (PTS!$E:$E="WTX") * ISNUMBER(PTS!AN:AN)))} -> 26.178082 | AJ5: {=AVERAGE(_xlfn._xlws.FILTER(PTS!AO:AO, (PTS!$E:$E="WTX") * ISNUMBER(PTS!AO:AO)))} -> 0 | AM5: {=AVERAGE(_xlfn._xlws.FILTER(PTS!AR:AR, (PTS!$E:$E="WTX") * ISNUMBER(PTS!AR:AR)))} -> 106.17808 | AQ5: =M5+R5+W5+AA5+AG5+AM5 -> 1222.4708 | AR5: =L5+R5+W5+AA5+AG5+AM5 -> 1433.6931
B6: WTXH | D6: {=AVERAGE(_xlfn._xlws.FILTER(PTS!I:I, (PTS!$E:$E="WTXH") * ISNUMBER(PTS!I:I)))} -> 93.845283 | E6: {=AVERAGE(_xlfn._xlws.FILTER(PTS!J:J, (PTS!$E:$E="WTXH") * ISNUMBER(PTS!J:J)))} -> 120.41509 | F6: {=AVERAGE(_xlfn._xlws.FILTER(PTS!K:K, (PTS!$E:$E="WTXH") * ISNUMBER(PTS!K:K)))} -> 206.95849 | G6: {=AVERAGE(_xlfn._xlws.FILTER(PTS!L:L, (PTS!$E:$E="WTXH") * ISNUMBER(PTS!L:L)))} -> 0 | H6: {=AVERAGE(_xlfn._xlws.FILTER(PTS!M:M, (PTS!$E:$E="WTXH") * ISNUMBER(PTS!M:M)))} -> 4.8679245 | I6: {=AVERAGE(_xlfn._xlws.FILTER(PTS!N:N, (PTS!$E:$E="WTXH") * ISNUMBER(PTS!N:N)))} -> 53.622642 | J6: {=AVERAGE(_xlfn._xlws.FILTER(PTS!O:O, (PTS!$E:$E="WTXH") * ISNUMBER(PTS!O:O)))} -> 37.916667 | K6: {=AVERAGE(_xlfn._xlws.FILTER(PTS!P:P, (PTS!$E:$E="WTXH") * ISNUMBER(PTS!P:P)))} -> 0 | L6: {=AVERAGE(_xlfn._xlws.FILTER(PTS!Q:Q, (PTS!$E:$E="WTXH") * ISNUMBER(PTS!Q:Q)))} -> 517.6261 | M6: {=AVERAGE(_xlfn._xlws.FILTER(PTS!R:R, (PTS!$E:$E="WTXH") * ISNUMBER(PTS!R:R)))} -> 308.68205 | N6: {=AVERAGE(_xlfn._xlws.FILTER(PTS!S:S, (PTS!$E:$E="WTXH") * ISNUMBER(PTS!S:S)))} -> 4.5283019 | O6: {=AVERAGE(_xlfn._xlws.FILTER(PTS!T:T, (PTS!$E:$E="WTXH") * ISNUMBER(PTS!T:T)))} -> 1.1320755 | P6: {=AVERAGE(_xlfn._xlws.FILTER(PTS!U:U, (PTS!$E:$E="WTXH") * ISNUMBER(PTS!U:U)))} -> 288.72326 | R6: {=AVERAGE(_xlfn._xlws.FILTER(PTS!W:W, (PTS!$E:$E="WTXH") * ISNUMBER(PTS!W:W)))} -> 294.60561 | S6: {=AVERAGE(_xlfn._xlws.FILTER(PTS!X:X, (PTS!$E:$E="WTXH") * ISNUMBER(PTS!X:X)))} -> 54 | T6: {=AVERAGE(_xlfn._xlws.FILTER(PTS!Y:Y, (PTS!$E:$E="WTXH") * ISNUMBER(PTS!Y:Y)))} -> 50.4 | U6: {=AVERAGE(_xlfn._xlws.FILTER(PTS!Z:Z, (PTS!$E:$E="WTXH") * ISNUMBER(PTS!Z:Z)))} -> 26.25 | W6: {=AVERAGE(_xlfn._xlws.FILTER(PTS!AB:AB, (PTS!$E:$E="WTXH") * ISNUMBER(PTS!AB:AB)))} -> 130.65 | X6: {=AVERAGE(_xlfn._xlws.FILTER(PTS!AC:AC, (PTS!$E:$E="STEX") * ISNUMBER(PTS!AC:AC)))} -> 133.97335 | Y6: {=AVERAGE(_xlfn._xlws.FILTER(PTS!AD:AD, (PTS!$E:$E="WTXH") * ISNUMBER(PTS!AD:AD)))} -> 197.95455 | AA6: {=AVERAGE(_xlfn._xlws.FILTER(PTS!AF:AF, (PTS!$E:$E="WTXH") * ISNUMBER(PTS!AF:AF)))} -> 330.90909 | AB6: {=AVERAGE(_xlfn._xlws.FILTER(PTS!AG:AG, (PTS!$E:$E="WTXH") * ISNUMBER(PTS!AG:AG)))} -> 28.8143 | AC6: {=AVERAGE(_xlfn._xlws.FILTER(PTS!AH:AH, (PTS!$E:$E="WTXH") * ISNUMBER(PTS!AH:AH)))} -> 6.9731405 | AD6: {=AVERAGE(_xlfn._xlws.FILTER(PTS!AI:AI, (PTS!$E:$E="WTXH") * ISNUMBER(PTS!AI:AI)))} -> 12.587317 | AE6: {=AVERAGE(_xlfn._xlws.FILTER(PTS!AJ:AJ, (PTS!$E:$E="WTXH") * ISNUMBER(PTS!AJ:AJ)))} -> 6.7352 | AG6: {=AVERAGE(_xlfn._xlws.FILTER(PTS!AL:AL, (PTS!$E:$E="WTXH") * ISNUMBER(PTS!AL:AL)))} -> 55.109958 | AH6: {=AVERAGE(_xlfn._xlws.FILTER(PTS!AM:AM, (PTS!$E:$E="WTXH") * ISNUMBER(PTS!AM:AM)))} -> 80 | AI6: {=AVERAGE(_xlfn._xlws.FILTER(PTS!AN:AN, (PTS!$E:$E="WTXH") * ISNUMBER(PTS!AN:AN)))} -> 26.178082 | AJ6: {=AVERAGE(_xlfn._xlws.FILTER(PTS!AO:AO, (PTS!$E:$E="WTXH") * ISNUMBER(PTS!AO:AO)))} -> 0 | AM6: {=AVERAGE(_xlfn._xlws.FILTER(PTS!AR:AR, (PTS!$E:$E="WTXH") * ISNUMBER(PTS!AR:AR)))} -> 106.17808 | AQ6: =M6+R6+W6+AA6+AG6+AM6 -> 1226.1348 | AR6: =L6+R6+W6+AA6+AG6+AM6 -> 1435.0788
B7: STEX | D7: {=AVERAGE(_xlfn._xlws.FILTER(PTS!I:I, (PTS!$E:$E="STEX") * ISNUMBER(PTS!I:I)))} -> 94.034483 | E7: {=AVERAGE(_xlfn._xlws.FILTER(PTS!J:J, (PTS!$E:$E="STEX") * ISNUMBER(PTS!J:J)))} -> 203.10345 | F7: {=AVERAGE(_xlfn._xlws.FILTER(PTS!K:K, (PTS!$E:$E="STEX") * ISNUMBER(PTS!K:K)))} -> 136.96552 | G7: {=AVERAGE(_xlfn._xlws.FILTER(PTS!L:L, (PTS!$E:$E="STEX") * ISNUMBER(PTS!L:L)))} -> 2.0689655 | H7: {=AVERAGE(_xlfn._xlws.FILTER(PTS!M:M, (PTS!$E:$E="STEX") * ISNUMBER(PTS!M:M)))} -> 7.1034483 | I7: {=AVERAGE(_xlfn._xlws.FILTER(PTS!N:N, (PTS!$E:$E="STEX") * ISNUMBER(PTS!N:N)))} -> 76.586207 | J7: {=AVERAGE(_xlfn._xlws.FILTER(PTS!O:O, (PTS!$E:$E="STEX") * ISNUMBER(PTS!O:O)))} -> 37.916667 | K7: {=AVERAGE(_xlfn._xlws.FILTER(PTS!P:P, (PTS!$E:$E="STEX") * ISNUMBER(PTS!P:P)))} -> 0 | L7: {=AVERAGE(_xlfn._xlws.FILTER(PTS!Q:Q, (PTS!$E:$E="STEX") * ISNUMBER(PTS!Q:Q)))} -> 557.77874 | M7: {=AVERAGE(_xlfn._xlws.FILTER(PTS!R:R, (PTS!$E:$E="STEX") * ISNUMBER(PTS!R:R)))} -> 452.33046 | N7: {=AVERAGE(_xlfn._xlws.FILTER(PTS!S:S, (PTS!$E:$E="STEX") * ISNUMBER(PTS!S:S)))} -> 4.8275862 | O7: {=AVERAGE(_xlfn._xlws.FILTER(PTS!T:T, (PTS!$E:$E="STEX") * ISNUMBER(PTS!T:T)))} -> 0 | P7: {=AVERAGE(_xlfn._xlws.FILTER(PTS!U:U, (PTS!$E:$E="STEX") * ISNUMBER(PTS!U:U)))} -> 200.75758 | R7: {=AVERAGE(_xlfn._xlws.FILTER(PTS!W:W, (PTS!$E:$E="STEX") * ISNUMBER(PTS!W:W)))} -> 205.94276 | S7: {=AVERAGE(_xlfn._xlws.FILTER(PTS!X:X, (PTS!$E:$E="STEX") * ISNUMBER(PTS!X:X)))} -> 54 | T7: {=AVERAGE(_xlfn._xlws.FILTER(PTS!Y:Y, (PTS!$E:$E="STEX") * ISNUMBER(PTS!Y:Y)))} -> 50.4 | U7: {=AVERAGE(_xlfn._xlws.FILTER(PTS!Z:Z, (PTS!$E:$E="STEX") * ISNUMBER(PTS!Z:Z)))} -> 26.25 | W7: {=AVERAGE(_xlfn._xlws.FILTER(PTS!AB:AB, (PTS!$E:$E="STEX") * ISNUMBER(PTS!AB:AB)))} -> 130.65 | X7: {=AVERAGE(_xlfn._xlws.FILTER(PTS!AC:AC, (PTS!$E:$E="STEX") * ISNUMBER(PTS!AC:AC)))} -> 133.97335 | Y7: {=AVERAGE(_xlfn._xlws.FILTER(PTS!AD:AD, (PTS!$E:$E="STEX") * ISNUMBER(PTS!AD:AD)))} -> 200.37618 | AA7: {=AVERAGE(_xlfn._xlws.FILTER(PTS!AF:AF, (PTS!$E:$E="STEX") * ISNUMBER(PTS!AF:AF)))} -> 334.34953 | AB7: {=AVERAGE(_xlfn._xlws.FILTER(PTS!AG:AG, (PTS!$E:$E="STEX") * ISNUMBER(PTS!AG:AG)))} -> 28.8143 | AC7: {=AVERAGE(_xlfn._xlws.FILTER(PTS!AH:AH, (PTS!$E:$E="STEX") * ISNUMBER(PTS!AH:AH)))} -> 6.9731405 | AD7: {=AVERAGE(_xlfn._xlws.FILTER(PTS!AI:AI, (PTS!$E:$E="STEX") * ISNUMBER(PTS!AI:AI)))} -> 12.587317 | AE7: {=AVERAGE(_xlfn._xlws.FILTER(PTS!AJ:AJ, (PTS!$E:$E="STEX") * ISNUMBER(PTS!AJ:AJ)))} -> 6.7352 | AG7: {=AVERAGE(_xlfn._xlws.FILTER(PTS!AL:AL, (PTS!$E:$E="STEX") * ISNUMBER(PTS!AL:AL)))} -> 55.109958 | AH7: {=AVERAGE(_xlfn._xlws.FILTER(PTS!AM:AM, (PTS!$E:$E="STEX") * ISNUMBER(PTS!AM:AM)))} -> 80 | AI7: {=AVERAGE(_xlfn._xlws.FILTER(PTS!AN:AN, (PTS!$E:$E="STEX") * ISNUMBER(PTS!AN:AN)))} -> 26.178082 | AJ7: {=AVERAGE(_xlfn._xlws.FILTER(PTS!AO:AO, (PTS!$E:$E="STEX") * ISNUMBER(PTS!AO:AO)))} -> 0 | AM7: {=AVERAGE(_xlfn._xlws.FILTER(PTS!AR:AR, (PTS!$E:$E="STEX") * ISNUMBER(PTS!AR:AR)))} -> 106.17808 | AQ7: =M7+R7+W7+AA7+AG7+AM7 -> 1284.5608 | AR7: =L7+R7+W7+AA7+AG7+AM7 -> 1390.0091
B8: Memphis Rule 5 | D8: {=AVERAGE(_xlfn._xlws.FILTER(PTS!I:I, (PTS!$E:$E="Memphis Rule 5") * ISNUMBER(PTS!I:I)))} -> 45.986667 | E8: {=AVERAGE(_xlfn._xlws.FILTER(PTS!J:J, (PTS!$E:$E="Memphis Rule 5") * ISNUMBER(PTS!J:J)))} -> 224.21333 | F8: {=AVERAGE(_xlfn._xlws.FILTER(PTS!K:K, (PTS!$E:$E="Memphis Rule 5") * ISNUMBER(PTS!K:K)))} -> 77.626667 | G8: {=AVERAGE(_xlfn._xlws.FILTER(PTS!L:L, (PTS!$E:$E="Memphis Rule 5") * ISNUMBER(PTS!L:L)))} -> 36.6 | H8: {=AVERAGE(_xlfn._xlws.FILTER(PTS!M:M, (PTS!$E:$E="Memphis Rule 5") * ISNUMBER(PTS!M:M)))} -> 3.8933333 | I8: {=AVERAGE(_xlfn._xlws.FILTER(PTS!N:N, (PTS!$E:$E="Memphis Rule 5") * ISNUMBER(PTS!N:N)))} -> 68.733333 | J8: {=AVERAGE(_xlfn._xlws.FILTER(PTS!O:O, (PTS!$E:$E="Memphis Rule 5") * ISNUMBER(PTS!O:O)))} -> 37.916667 | K8: {=AVERAGE(_xlfn._xlws.FILTER(PTS!P:P, (PTS!$E:$E="Memphis Rule 5") * ISNUMBER(PTS!P:P)))} -> 0 | L8: {=AVERAGE(_xlfn._xlws.FILTER(PTS!Q:Q, (PTS!$E:$E="Memphis Rule 5") * ISNUMBER(PTS!Q:Q)))} -> 494.97 | M8: {=AVERAGE(_xlfn._xlws.FILTER(PTS!R:R, (PTS!$E:$E="Memphis Rule 5") * ISNUMBER(PTS!R:R)))} -> 106.65 | N8: {=AVERAGE(_xlfn._xlws.FILTER(PTS!S:S, (PTS!$E:$E="Memphis Rule 5") * ISNUMBER(PTS!S:S)))} -> 0.26666667 | O8: {=AVERAGE(_xlfn._xlws.FILTER(PTS!T:T, (PTS!$E:$E="Memphis Rule 5") * ISNUMBER(PTS!T:T)))} -> 0.73333333 | P8: {=AVERAGE(_xlfn._xlws.FILTER(PTS!U:U, (PTS!$E:$E="Memphis Rule 5") * ISNUMBER(PTS!U:U)))} -> 211.56873 | R8: {=AVERAGE(_xlfn._xlws.FILTER(PTS!W:W, (PTS!$E:$E="Memphis Rule 5") * ISNUMBER(PTS!W:W)))} -> 212.56873 | S8: {=AVERAGE(_xlfn._xlws.FILTER(PTS!X:X, (PTS!$E:$E="Memphis Rule 5") * ISNUMBER(PTS!X:X)))} -> 50.48 | T8: {=AVERAGE(_xlfn._xlws.FILTER(PTS!Y:Y, (PTS!$E:$E="Memphis Rule 5") * ISNUMBER(PTS!Y:Y)))} -> 35.616 | U8: {=AVERAGE(_xlfn._xlws.FILTER(PTS!Z:Z, (PTS!$E:$E="Memphis Rule 5") * ISNUMBER(PTS!Z:Z)))} -> 26.25 | W8: {=AVERAGE(_xlfn._xlws.FILTER(PTS!AB:AB, (PTS!$E:$E="Memphis Rule 5") * ISNUMBER(PTS!AB:AB)))} -> 112.346 | X8: {=AVERAGE(_xlfn._xlws.FILTER(PTS!AC:AC, (PTS!$E:$E="Memphis Rule 5") * ISNUMBER(PTS!AC:AC)))} -> 144.45455 | Y8: {=AVERAGE(_xlfn._xlws.FILTER(PTS!AD:AD, (PTS!$G:$G="Memphis") * ISNUMBER(PTS!AD:AD)))} -> 182.72727 | AA8: {=AVERAGE(_xlfn._xlws.FILTER(PTS!AF:AF, (PTS!$G:$G="Memphis") * ISNUMBER(PTS!AF:AF)))} -> 328.75 | AB8: {=AVERAGE(_xlfn._xlws.FILTER(PTS!AG:AG, (PTS!$E:$E="Memphis Rule 5") * ISNUMBER(PTS!AG:AG)))} -> 28.8143 | AC8: {=AVERAGE(_xlfn._xlws.FILTER(PTS!AH:AH, (PTS!$E:$E="Memphis Rule 5") * ISNUMBER(PTS!AH:AH)))} -> 6.9731405 | AD8: {=AVERAGE(_xlfn._xlws.FILTER(PTS!AI:AI, (PTS!$E:$E="Memphis Rule 5") * ISNUMBER(PTS!AI:AI)))} -> 12.587317 | AE8: {=AVERAGE(_xlfn._xlws.FILTER(PTS!AJ:AJ, (PTS!$E:$E="Memphis Rule 5") * ISNUMBER(PTS!AJ:AJ)))} -> 6.7352 | AG8: {=AVERAGE(_xlfn._xlws.FILTER(PTS!AL:AL, (PTS!$E:$E="Memphis Rule 5") * ISNUMBER(PTS!AL:AL)))} -> 55.109958 | AH8: {=AVERAGE(_xlfn._xlws.FILTER(PTS!AM:AM, (PTS!$E:$E="Memphis Rule 5") * ISNUMBER(PTS!AM:AM)))} -> 80 | AI8: {=AVERAGE(_xlfn._xlws.FILTER(PTS!AN:AN, (PTS!$E:$E="Memphis Rule 5") * ISNUMBER(PTS!AN:AN)))} -> 26.178082 | AJ8: {=AVERAGE(_xlfn._xlws.FILTER(PTS!AO:AO, (PTS!$E:$E="Memphis Rule 5") * ISNUMBER(PTS!AO:AO)))} -> 0 | AM8: {=AVERAGE(_xlfn._xlws.FILTER(PTS!AR:AR, (PTS!$E:$E="Memphis Rule 5") * ISNUMBER(PTS!AR:AR)))} -> 106.17808 | AQ8: =M8+R8+W8+AA8+AG8+AM8 -> 921.60277 | AR8: =L8+R8+W8+AA8+AG8+AM8 -> 1309.9228
B9: GA 30 Day | D9: {=AVERAGE(_xlfn._xlws.FILTER(PTS!I:I, (PTS!$E:$E="Memphis Rule 5") * ISNUMBER(PTS!I:I)))} -> 45.986667 | E9: {=AVERAGE(_xlfn._xlws.FILTER(PTS!J:J, (PTS!$E:$E="GA 30 Day") * ISNUMBER(PTS!J:J)))} -> 88.478261 | F9: {=AVERAGE(_xlfn._xlws.FILTER(PTS!K:K, (PTS!$E:$E="GA 30 Day") * ISNUMBER(PTS!K:K)))} -> 18.84058 | G9: {=AVERAGE(_xlfn._xlws.FILTER(PTS!L:L, (PTS!$E:$E="GA 30 Day") * ISNUMBER(PTS!L:L)))} -> 1.7681159 | H9: {=AVERAGE(_xlfn._xlws.FILTER(PTS!M:M, (PTS!$E:$E="GA 30 Day") * ISNUMBER(PTS!M:M)))} -> 12.782609 | I9: {=AVERAGE(_xlfn._xlws.FILTER(PTS!N:N, (PTS!$E:$E="GA 30 Day") * ISNUMBER(PTS!N:N)))} -> 57.318841 | J9: {=AVERAGE(_xlfn._xlws.FILTER(PTS!O:O, (PTS!$E:$E="GA 30 Day") * ISNUMBER(PTS!O:O)))} -> 37.916667 | K9: {=AVERAGE(_xlfn._xlws.FILTER(PTS!P:P, (PTS!$E:$E="GA 30 Day") * ISNUMBER(PTS!P:P)))} -> 0 | L9: {=AVERAGE(_xlfn._xlws.FILTER(PTS!Q:Q, (PTS!$E:$E="GA 30 Day") * ISNUMBER(PTS!Q:Q)))} -> 276.61232 | M9: {=AVERAGE(_xlfn._xlws.FILTER(PTS!R:R, (PTS!$E:$E="GA 30 Day") * ISNUMBER(PTS!R:R)))} -> 41.307971 | N9: {=AVERAGE(_xlfn._xlws.FILTER(PTS!S:S, (PTS!$E:$E="GA 30 Day") * ISNUMBER(PTS!S:S)))} -> 0 | O9: {=AVERAGE(_xlfn._xlws.FILTER(PTS!T:T, (PTS!$E:$E="GA 30 Day") * ISNUMBER(PTS!T:T)))} -> 0.82345191 | P9: {=AVERAGE(_xlfn._xlws.FILTER(PTS!U:U, (PTS!$E:$E="GA 30 Day") * ISNUMBER(PTS!U:U)))} -> 203.95335 | R9: {=AVERAGE(_xlfn._xlws.FILTER(PTS!W:W, (PTS!$E:$E="GA 30 Day") * ISNUMBER(PTS!W:W)))} -> 204.78891 | S9: {=AVERAGE(_xlfn._xlws.FILTER(PTS!X:X, (PTS!$E:$E="GA 30 Day") * ISNUMBER(PTS!X:X)))} -> 52 | T9: {=AVERAGE(_xlfn._xlws.FILTER(PTS!Y:Y, (PTS!$E:$E="GA 30 Day") * ISNUMBER(PTS!Y:Y)))} -> 50.4 | U9: {=AVERAGE(_xlfn._xlws.FILTER(PTS!Z:Z, (PTS!$E:$E="GA 30 Day") * ISNUMBER(PTS!Z:Z)))} -> 26.25 | W9: {=AVERAGE(_xlfn._xlws.FILTER(PTS!AB:AB, (PTS!$E:$E="GA 30 Day") * ISNUMBER(PTS!AB:AB)))} -> 128.65 | X9: {=AVERAGE(_xlfn._xlws.FILTER(PTS!AC:AC, (PTS!$E:$E="GA 30 Day") * ISNUMBER(PTS!AC:AC)))} -> 110.22727 | Y9: {=AVERAGE(_xlfn._xlws.FILTER(PTS!AD:AD, (PTS!$E:$E="GA 30 Day") * ISNUMBER(PTS!AD:AD)))} -> 107.04545 | AA9: {=AVERAGE(_xlfn._xlws.FILTER(PTS!AF:AF, (PTS!$E:$E="GA 30 Day") * ISNUMBER(PTS!AF:AF)))} -> 217.27273 | AB9: {=AVERAGE(_xlfn._xlws.FILTER(PTS!AG:AG, (PTS!$E:$E="GA 30 Day") * ISNUMBER(PTS!AG:AG)))} -> 28.8143 | AC9: {=AVERAGE(_xlfn._xlws.FILTER(PTS!AH:AH, (PTS!$E:$E="GA 30 Day") * ISNUMBER(PTS!AH:AH)))} -> 6.9731405 | AD9: {=AVERAGE(_xlfn._xlws.FILTER(PTS!AI:AI, (PTS!$E:$E="GA 30 Day") * ISNUMBER(PTS!AI:AI)))} -> 12.587317 | AE9: {=AVERAGE(_xlfn._xlws.FILTER(PTS!AJ:AJ, (PTS!$E:$E="GA 30 Day") * ISNUMBER(PTS!AJ:AJ)))} -> 6.7352 | AG9: {=AVERAGE(_xlfn._xlws.FILTER(PTS!AL:AL, (PTS!$E:$E="GA 30 Day") * ISNUMBER(PTS!AL:AL)))} -> 55.109958 | AH9: {=AVERAGE(_xlfn._xlws.FILTER(PTS!AM:AM, (PTS!$E:$E="GA 30 Day") * ISNUMBER(PTS!AM:AM)))} -> 80 | AI9: {=AVERAGE(_xlfn._xlws.FILTER(PTS!AN:AN, (PTS!$E:$E="GA 30 Day") * ISNUMBER(PTS!AN:AN)))} -> 26.178082 | AJ9: {=AVERAGE(_xlfn._xlws.FILTER(PTS!AO:AO, (PTS!$E:$E="GA 30 Day") * ISNUMBER(PTS!AO:AO)))} -> 0 | AM9: {=AVERAGE(_xlfn._xlws.FILTER(PTS!AR:AR, (PTS!$E:$E="GA 30 Day") * ISNUMBER(PTS!AR:AR)))} -> 106.17808 | AQ9: =M9+R9+W9+AA9+AG9+AM9 -> 753.30765 | AR9: =L9+R9+W9+AA9+AG9+AM9 -> 988.612
B10: Eastern Rule 5 | D10: {=AVERAGE(_xlfn._xlws.FILTER(PTS!I:I, (PTS!$E:$E="Eastern Rule 5") * ISNUMBER(PTS!I:I)))} -> 66.135802 | E10: {=AVERAGE(_xlfn._xlws.FILTER(PTS!J:J, (PTS!$E:$E="Eastern Rule 5") * ISNUMBER(PTS!J:J)))} -> 92.407407 | F10: {=AVERAGE(_xlfn._xlws.FILTER(PTS!K:K, (PTS!$E:$E="Eastern Rule 5") * ISNUMBER(PTS!K:K)))} -> 20.617284 | G10: {=AVERAGE(_xlfn._xlws.FILTER(PTS!L:L, (PTS!$E:$E="Eastern Rule 5") * ISNUMBER(PTS!L:L)))} -> 2.5308642 | H10: {=AVERAGE(_xlfn._xlws.FILTER(PTS!M:M, (PTS!$E:$E="Eastern Rule 5") * ISNUMBER(PTS!M:M)))} -> 9.617284 | I10: {=AVERAGE(_xlfn._xlws.FILTER(PTS!N:N, (PTS!$E:$E="Eastern Rule 5") * ISNUMBER(PTS!N:N)))} -> 48.120988 | J10: {=AVERAGE(_xlfn._xlws.FILTER(PTS!O:O, (PTS!$E:$E="Eastern Rule 5") * ISNUMBER(PTS!O:O)))} -> 37.916667 | K10: {=AVERAGE(_xlfn._xlws.FILTER(PTS!P:P, (PTS!$E:$E="Eastern Rule 5") * ISNUMBER(PTS!P:P)))} -> 0 | L10: {=AVERAGE(_xlfn._xlws.FILTER(PTS!Q:Q, (PTS!$E:$E="Eastern Rule 5") * ISNUMBER(PTS!Q:Q)))} -> 277.3463 | M10: {=AVERAGE(_xlfn._xlws.FILTER(PTS!R:R, (PTS!$E:$E="Eastern Rule 5") * ISNUMBER(PTS!R:R)))} -> 86.037654 | N10: {=AVERAGE(_xlfn._xlws.FILTER(PTS!S:S, (PTS!$E:$E="Eastern Rule 5") * ISNUMBER(PTS!S:S)))} -> 0 | O10: {=AVERAGE(_xlfn._xlws.FILTER(PTS!T:T, (PTS!$E:$E="Eastern Rule 5") * ISNUMBER(PTS!T:T)))} -> 0 | P10: {=AVERAGE(_xlfn._xlws.FILTER(PTS!U:U, (PTS!$E:$E="Eastern Rule 5") * ISNUMBER(PTS!U:U)))} -> 271.21305 | R10: {=AVERAGE(_xlfn._xlws.FILTER(PTS!W:W, (PTS!$G:$G="Savannah") * ISNUMBER(PTS!W:W)))} -> 241.12586 | S10: {=AVERAGE(_xlfn._xlws.FILTER(PTS!X:X, (PTS!$E:$E="Eastern Rule 5") * ISNUMBER(PTS!X:X)))} -> 51.802469 | T10: {=AVERAGE(_xlfn._xlws.FILTER(PTS!Y:Y, (PTS!$G:$G="Savannah") * ISNUMBER(PTS!Y:Y)))} -> 50.4 | U10: {=AVERAGE(_xlfn._xlws.FILTER(PTS!Z:Z, (PTS!$E:$E="Eastern Rule 5") * ISNUMBER(PTS!Z:Z)))} -> 26.25 | W10: {=AVERAGE(_xlfn._xlws.FILTER(PTS!AB:AB, (PTS!$E:$E="Eastern Rule 5") * ISNUMBER(PTS!AB:AB)))} -> 126.79321 | X10: {=AVERAGE(_xlfn._xlws.FILTER(PTS!AC:AC, (PTS!$E:$E="Eastern Rule 5") * ISNUMBER(PTS!AC:AC)))} -> 113.76263 | Y10: {=AVERAGE(_xlfn._xlws.FILTER(PTS!AD:AD, (PTS!$E:$E="Eastern Rule 5") * ISNUMBER(PTS!AD:AD)))} -> 114.5202 | AA10: {=AVERAGE(_xlfn._xlws.FILTER(PTS!AF:AF, (PTS!$E:$E="Eastern Rule 5") * ISNUMBER(PTS!AF:AF)))} -> 228.28283 | AB10: {=AVERAGE(_xlfn._xlws.FILTER(PTS!AG:AG, (PTS!$E:$E="Eastern Rule 5") * ISNUMBER(PTS!AG:AG)))} -> 28.8143 | AC10: {=AVERAGE(_xlfn._xlws.FILTER(PTS!AH:AH, (PTS!$E:$E="Eastern Rule 5") * ISNUMBER(PTS!AH:AH)))} -> 6.9731405 | AD10: {=AVERAGE(_xlfn._xlws.FILTER(PTS!AI:AI, (PTS!$E:$E="Eastern Rule 5") * ISNUMBER(PTS!AI:AI)))} -> 12.587317 | AE10: {=AVERAGE(_xlfn._xlws.FILTER(PTS!AJ:AJ, (PTS!$E:$E="Eastern Rule 5") * ISNUMBER(PTS!AJ:AJ)))} -> 6.7352 | AG10: {=AVERAGE(_xlfn._xlws.FILTER(PTS!AL:AL, (PTS!$E:$E="Eastern Rule 5") * ISNUMBER(PTS!AL:AL)))} -> 55.109958 | AH10: {=AVERAGE(_xlfn._xlws.FILTER(PTS!AM:AM, (PTS!$E:$E="Eastern Rule 5") * ISNUMBER(PTS!AM:AM)))} -> 80 | AI10: {=AVERAGE(_xlfn._xlws.FILTER(PTS!AN:AN, (PTS!$E:$E="Eastern Rule 5") * ISNUMBER(PTS!AN:AN)))} -> 26.178082 | AJ10: {=AVERAGE(_xlfn._xlws.FILTER(PTS!AO:AO, (PTS!$E:$E="Eastern Rule 5") * ISNUMBER(PTS!AO:AO)))} -> 0 | AM10: {=AVERAGE(_xlfn._xlws.FILTER(PTS!AR:AR, (PTS!$E:$E="Eastern Rule 5") * ISNUMBER(PTS!AR:AR)))} -> 106.17808 | AQ10: =M10+R10+W10+AA10+AG10+AM10 -> 843.52759 | AR10: =L10+R10+W10+AA10+AG10+AM10 -> 1034.8362
B11: WTEX Equity | D11: {=AVERAGE(_xlfn._xlws.FILTER(PTS!I:I, (PTS!$E:$E="WTX") * ISNUMBER(PTS!I:I)))} -> 93.277193 | E11: {=AVERAGE(_xlfn._xlws.FILTER(PTS!J:J, (PTS!$E:$E="WTX") * ISNUMBER(PTS!J:J)))} -> 124.68421 | F11: {=AVERAGE(_xlfn._xlws.FILTER(PTS!K:K, (PTS!$E:$E="WTX") * ISNUMBER(PTS!K:K)))} -> 203.04912 | G11: {=AVERAGE(_xlfn._xlws.FILTER(PTS!L:L, (PTS!$E:$E="WTX") * ISNUMBER(PTS!L:L)))} -> 0 | H11: {=AVERAGE(_xlfn._xlws.FILTER(PTS!M:M, (PTS!$E:$E="WTX") * ISNUMBER(PTS!M:M)))} -> 4.5263158 | I11: {=AVERAGE(_xlfn._xlws.FILTER(PTS!N:N, (PTS!$E:$E="WTX") * ISNUMBER(PTS!N:N)))} -> 54.473684 | J11: {=AVERAGE(_xlfn._xlws.FILTER(PTS!O:O, (PTS!$E:$E="WTX") * ISNUMBER(PTS!O:O)))} -> 37.916667 | K11: {=AVERAGE(_xlfn._xlws.FILTER(PTS!P:P, (PTS!$E:$E="WTX") * ISNUMBER(PTS!P:P)))} -> 0 | L11: {=AVERAGE(_xlfn._xlws.FILTER(PTS!Q:Q, (PTS!$E:$E="WTX") * ISNUMBER(PTS!Q:Q)))} -> 518.74259 | M11: {=AVERAGE(_xlfn._xlws.FILTER(PTS!R:R, (PTS!$E:$E="WTX") * ISNUMBER(PTS!R:R)))} -> 307.52024 | N11: {=AVERAGE(_xlfn._xlws.FILTER(PTS!S:S, (PTS!$E:$E="WTX") * ISNUMBER(PTS!S:S)))} -> 4.9122807 | O11: {=AVERAGE(_xlfn._xlws.FILTER(PTS!T:T, (PTS!$E:$E="WTX") * ISNUMBER(PTS!T:T)))} -> 1.1403509 | P11: {=AVERAGE(_xlfn._xlws.FILTER(PTS!U:U, (PTS!$E:$E="WTX") * ISNUMBER(PTS!U:U)))} -> 186.05615 | R11: {=AVERAGE(_xlfn._xlws.FILTER(PTS!W:W, (PTS!$E:$E="WTX") * ISNUMBER(PTS!W:W)))} -> 192.33066 | S11: {=AVERAGE(_xlfn._xlws.FILTER(PTS!X:X, (PTS!$E:$E="WTX") * ISNUMBER(PTS!X:X)))} -> 54 | T11: {=AVERAGE(_xlfn._xlws.FILTER(PTS!Y:Y, (PTS!$E:$E="WTX") * ISNUMBER(PTS!Y:Y)))} -> 50.4 | U11: {=AVERAGE(_xlfn._xlws.FILTER(PTS!Z:Z, (PTS!$E:$E="WTX") * ISNUMBER(PTS!Z:Z)))} -> 26.25 | W11: {=AVERAGE(_xlfn._xlws.FILTER(PTS!AB:AB, (PTS!$E:$E="WTX") * ISNUMBER(PTS!AB:AB)))} -> 130.65 | X11: {=AVERAGE(_xlfn._xlws.FILTER(PTS!AC:AC, (PTS!$E:$E="WTX") * ISNUMBER(PTS!AC:AC)))} -> 162.5 | Y11: {=AVERAGE(_xlfn._xlws.FILTER(PTS!AD:AD, (PTS!$E:$E="WTX") * ISNUMBER(PTS!AD:AD)))} -> 268.18182 | AA11: {=AVERAGE(_xlfn._xlws.FILTER(PTS!AF:AF, (PTS!$E:$E="WTX") * ISNUMBER(PTS!AF:AF)))} -> 430.68182 | AB11: {=AVERAGE(_xlfn._xlws.FILTER(PTS!AG:AG, (PTS!$E:$E="WTX") * ISNUMBER(PTS!AG:AG)))} -> 28.8143 | AC11: {=AVERAGE(_xlfn._xlws.FILTER(PTS!AH:AH, (PTS!$E:$E="WTX") * ISNUMBER(PTS!AH:AH)))} -> 6.9731405 | AD11: {=AVERAGE(_xlfn._xlws.FILTER(PTS!AI:AI, (PTS!$E:$E="WTX") * ISNUMBER(PTS!AI:AI)))} -> 12.587317 | AE11: {=AVERAGE(_xlfn._xlws.FILTER(PTS!AJ:AJ, (PTS!$E:$E="WTX") * ISNUMBER(PTS!AJ:AJ)))} -> 6.7352 | AG11: {=AVERAGE(_xlfn._xlws.FILTER(PTS!AL:AL, (PTS!$E:$E="WTX") * ISNUMBER(PTS!AL:AL)))} -> 55.109958 | AH11: {=AVERAGE(_xlfn._xlws.FILTER(PTS!AM:AM, (PTS!$E:$E="WTX") * ISNUMBER(PTS!AM:AM)))} -> 80 | AI11: {=AVERAGE(_xlfn._xlws.FILTER(PTS!AN:AN, (PTS!$E:$E="WTX") * ISNUMBER(PTS!AN:AN)))} -> 26.178082 | AJ11: {=AVERAGE(_xlfn._xlws.FILTER(PTS!AO:AO, (PTS!$E:$E="WTX") * ISNUMBER(PTS!AO:AO)))} -> 0 | AM11: {=AVERAGE(_xlfn._xlws.FILTER(PTS!AR:AR, (PTS!$E:$E="WTX") * ISNUMBER(PTS!AR:AR)))} -> 106.17808 | AQ11: =M11+R11+W11+AA11+AG11+AM11 -> 1222.4708 | AR11: =L11+R11+W11+AA11+AG11+AM11 -> 1433.6931
B12: STEX Equity | D12: {=AVERAGE(_xlfn._xlws.FILTER(PTS!I:I, (PTS!$E:$E="STEX") * ISNUMBER(PTS!I:I)))} -> 94.034483 | E12: {=AVERAGE(_xlfn._xlws.FILTER(PTS!J:J, (PTS!$E:$E="STEX") * ISNUMBER(PTS!J:J)))} -> 203.10345 | F12: {=AVERAGE(_xlfn._xlws.FILTER(PTS!K:K, (PTS!$E:$E="STEX") * ISNUMBER(PTS!K:K)))} -> 136.96552 | G12: {=AVERAGE(_xlfn._xlws.FILTER(PTS!L:L, (PTS!$E:$E="STEX") * ISNUMBER(PTS!L:L)))} -> 2.0689655 | H12: {=AVERAGE(_xlfn._xlws.FILTER(PTS!M:M, (PTS!$E:$E="STEX") * ISNUMBER(PTS!M:M)))} -> 7.1034483 | I12: {=AVERAGE(_xlfn._xlws.FILTER(PTS!N:N, (PTS!$E:$E="STEX") * ISNUMBER(PTS!N:N)))} -> 76.586207 | J12: {=AVERAGE(_xlfn._xlws.FILTER(PTS!O:O, (PTS!$E:$E="STEX") * ISNUMBER(PTS!O:O)))} -> 37.916667 | K12: {=AVERAGE(_xlfn._xlws.FILTER(PTS!P:P, (PTS!$E:$E="STEX") * ISNUMBER(PTS!P:P)))} -> 0 | L12: {=AVERAGE(_xlfn._xlws.FILTER(PTS!Q:Q, (PTS!$E:$E="STEX") * ISNUMBER(PTS!Q:Q)))} -> 557.77874 | M12: {=AVERAGE(_xlfn._xlws.FILTER(PTS!R:R, (PTS!$E:$E="STEX") * ISNUMBER(PTS!R:R)))} -> 452.33046 | N12: {=AVERAGE(_xlfn._xlws.FILTER(PTS!S:S, (PTS!$E:$E="STEX") * ISNUMBER(PTS!S:S)))} -> 4.8275862 | O12: {=AVERAGE(_xlfn._xlws.FILTER(PTS!T:T, (PTS!$E:$E="STEX") * ISNUMBER(PTS!T:T)))} -> 0 | P12: {=AVERAGE(_xlfn._xlws.FILTER(PTS!U:U, (PTS!$E:$E="STEX") * ISNUMBER(PTS!U:U)))} -> 200.75758 | R12: {=AVERAGE(_xlfn._xlws.FILTER(PTS!W:W, (PTS!$E:$E="STEX") * ISNUMBER(PTS!W:W)))} -> 205.94276 | S12: {=AVERAGE(_xlfn._xlws.FILTER(PTS!X:X, (PTS!$E:$E="STEX") * ISNUMBER(PTS!X:X)))} -> 54 | T12: {=AVERAGE(_xlfn._xlws.FILTER(PTS!Y:Y, (PTS!$E:$E="STEX") * ISNUMBER(PTS!Y:Y)))} -> 50.4 | U12: {=AVERAGE(_xlfn._xlws.FILTER(PTS!Z:Z, (PTS!$E:$E="STEX") * ISNUMBER(PTS!Z:Z)))} -> 26.25 | W12: {=AVERAGE(_xlfn._xlws.FILTER(PTS!AB:AB, (PTS!$E:$E="STEX") * ISNUMBER(PTS!AB:AB)))} -> 130.65 | X12: {=AVERAGE(_xlfn._xlws.FILTER(PTS!AC:AC, (PTS!$E:$E="STEX") * ISNUMBER(PTS!AC:AC)))} -> 133.97335 | Y12: {=AVERAGE(_xlfn._xlws.FILTER(PTS!AD:AD, (PTS!$E:$E="STEX") * ISNUMBER(PTS!AD:AD)))} -> 200.37618 | AA12: {=AVERAGE(_xlfn._xlws.FILTER(PTS!AF:AF, (PTS!$E:$E="STEX") * ISNUMBER(PTS!AF:AF)))} -> 334.34953 | AB12: {=AVERAGE(_xlfn._xlws.FILTER(PTS!AG:AG, (PTS!$E:$E="STEX") * ISNUMBER(PTS!AG:AG)))} -> 28.8143 | AC12: {=AVERAGE(_xlfn._xlws.FILTER(PTS!AH:AH, (PTS!$E:$E="STEX") * ISNUMBER(PTS!AH:AH)))} -> 6.9731405 | AD12: {=AVERAGE(_xlfn._xlws.FILTER(PTS!AI:AI, (PTS!$E:$E="STEX") * ISNUMBER(PTS!AI:AI)))} -> 12.587317 | AE12: {=AVERAGE(_xlfn._xlws.FILTER(PTS!AJ:AJ, (PTS!$E:$E="STEX") * ISNUMBER(PTS!AJ:AJ)))} -> 6.7352 | AG12: {=AVERAGE(_xlfn._xlws.FILTER(PTS!AL:AL, (PTS!$E:$E="STEX") * ISNUMBER(PTS!AL:AL)))} -> 55.109958 | AH12: {=AVERAGE(_xlfn._xlws.FILTER(PTS!AM:AM, (PTS!$E:$E="STEX") * ISNUMBER(PTS!AM:AM)))} -> 80 | AI12: {=AVERAGE(_xlfn._xlws.FILTER(PTS!AN:AN, (PTS!$E:$E="STEX") * ISNUMBER(PTS!AN:AN)))} -> 26.178082 | AJ12: {=AVERAGE(_xlfn._xlws.FILTER(PTS!AO:AO, (PTS!$E:$E="STEX") * ISNUMBER(PTS!AO:AO)))} -> 0 | AM12: {=AVERAGE(_xlfn._xlws.FILTER(PTS!AR:AR, (PTS!$E:$E="STEX") * ISNUMBER(PTS!AR:AR)))} -> 106.17808 | AQ12: =M12+R12+W12+AA12+AG12+AM12 -> 1284.5608 | AR12: =L12+R12+W12+AA12+AG12+AM12 -> 1390.0091
B13: Memphis Equity | D13: {=AVERAGE(_xlfn._xlws.FILTER(PTS!I:I, (PTS!$E:$E="STEX") * ISNUMBER(PTS!I:I)))} -> 94.034483 | E13: {=AVERAGE(_xlfn._xlws.FILTER(PTS!J:J, (PTS!$E:$E="Memphis Rule 5") * ISNUMBER(PTS!J:J)))} -> 224.21333 | F13: {=AVERAGE(_xlfn._xlws.FILTER(PTS!K:K, (PTS!$E:$E="Memphis Rule 5") * ISNUMBER(PTS!K:K)))} -> 77.626667 | G13: {=AVERAGE(_xlfn._xlws.FILTER(PTS!L:L, (PTS!$E:$E="Memphis Rule 5") * ISNUMBER(PTS!L:L)))} -> 36.6 | H13: {=AVERAGE(_xlfn._xlws.FILTER(PTS!M:M, (PTS!$E:$E="Memphis Rule 5") * ISNUMBER(PTS!M:M)))} -> 3.8933333 | I13: {=AVERAGE(_xlfn._xlws.FILTER(PTS!N:N, (PTS!$E:$E="Memphis Rule 5") * ISNUMBER(PTS!N:N)))} -> 68.733333 | J13: {=AVERAGE(_xlfn._xlws.FILTER(PTS!O:O, (PTS!$E:$E="Memphis Rule 5") * ISNUMBER(PTS!O:O)))} -> 37.916667 | K13: {=AVERAGE(_xlfn._xlws.FILTER(PTS!P:P, (PTS!$E:$E="Memphis Rule 5") * ISNUMBER(PTS!P:P)))} -> 0 | L13: {=AVERAGE(_xlfn._xlws.FILTER(PTS!Q:Q, (PTS!$E:$E="Memphis Rule 5") * ISNUMBER(PTS!Q:Q)))} -> 494.97 | M13: {=AVERAGE(_xlfn._xlws.FILTER(PTS!R:R, (PTS!$E:$E="Memphis Rule 5") * ISNUMBER(PTS!R:R)))} -> 106.65 | N13: {=AVERAGE(_xlfn._xlws.FILTER(PTS!S:S, (PTS!$E:$E="Memphis Rule 5") * ISNUMBER(PTS!S:S)))} -> 0.26666667 | O13: {=AVERAGE(_xlfn._xlws.FILTER(PTS!T:T, (PTS!$E:$E="Memphis Rule 5") * ISNUMBER(PTS!T:T)))} -> 0.73333333 | P13: {=AVERAGE(_xlfn._xlws.FILTER(PTS!U:U, (PTS!$E:$E="Memphis Rule 5") * ISNUMBER(PTS!U:U)))} -> 211.56873 | R13: {=AVERAGE(_xlfn._xlws.FILTER(PTS!W:W, (PTS!$E:$E="Memphis Rule 5") * ISNUMBER(PTS!W:W)))} -> 212.56873 | S13: {=AVERAGE(_xlfn._xlws.FILTER(PTS!X:X, (PTS!$E:$E="Memphis Rule 5") * ISNUMBER(PTS!X:X)))} -> 50.48 | T13: {=AVERAGE(_xlfn._xlws.FILTER(PTS!Y:Y, (PTS!$E:$E="Memphis Rule 5") * ISNUMBER(PTS!Y:Y)))} -> 35.616 | U13: {=AVERAGE(_xlfn._xlws.FILTER(PTS!Z:Z, (PTS!$E:$E="Memphis Rule 5") * ISNUMBER(PTS!Z:Z)))} -> 26.25 | W13: {=AVERAGE(_xlfn._xlws.FILTER(PTS!AB:AB, (PTS!$E:$E="Memphis Rule 5") * ISNUMBER(PTS!AB:AB)))} -> 112.346 | X13: {=AVERAGE(_xlfn._xlws.FILTER(PTS!AC:AC, (PTS!$E:$E="Memphis Rule 5") * ISNUMBER(PTS!AC:AC)))} -> 144.45455 | Y13: {=AVERAGE(_xlfn._xlws.FILTER(PTS!AD:AD, (PTS!$E:$E="Memphis Rule 5") * ISNUMBER(PTS!AD:AD)))} -> 184.55455 | AA13: {=AVERAGE(_xlfn._xlws.FILTER(PTS!AF:AF, (PTS!$E:$E="Memphis Rule 5") * ISNUMBER(PTS!AF:AF)))} -> 329.00909 | AB13: {=AVERAGE(_xlfn._xlws.FILTER(PTS!AG:AG, (PTS!$E:$E="Memphis Rule 5") * ISNUMBER(PTS!AG:AG)))} -> 28.8143 | AC13: {=AVERAGE(_xlfn._xlws.FILTER(PTS!AH:AH, (PTS!$E:$E="Memphis Rule 5") * ISNUMBER(PTS!AH:AH)))} -> 6.9731405 | AD13: {=AVERAGE(_xlfn._xlws.FILTER(PTS!AI:AI, (PTS!$E:$E="Memphis Rule 5") * ISNUMBER(PTS!AI:AI)))} -> 12.587317 | AE13: {=AVERAGE(_xlfn._xlws.FILTER(PTS!AJ:AJ, (PTS!$E:$E="Memphis Rule 5") * ISNUMBER(PTS!AJ:AJ)))} -> 6.7352 | AG13: {=AVERAGE(_xlfn._xlws.FILTER(PTS!AL:AL, (PTS!$E:$E="Memphis Rule 5") * ISNUMBER(PTS!AL:AL)))} -> 55.109958 | AH13: {=AVERAGE(_xlfn._xlws.FILTER(PTS!AM:AM, (PTS!$E:$E="Memphis Rule 5") * ISNUMBER(PTS!AM:AM)))} -> 80 | AI13: {=AVERAGE(_xlfn._xlws.FILTER(PTS!AN:AN, (PTS!$E:$E="Memphis Rule 5") * ISNUMBER(PTS!AN:AN)))} -> 26.178082 | AJ13: {=AVERAGE(_xlfn._xlws.FILTER(PTS!AO:AO, (PTS!$E:$E="Memphis Rule 5") * ISNUMBER(PTS!AO:AO)))} -> 0 | AM13: {=AVERAGE(_xlfn._xlws.FILTER(PTS!AR:AR, (PTS!$E:$E="Memphis Rule 5") * ISNUMBER(PTS!AR:AR)))} -> 106.17808 | AQ13: =M13+R13+W13+AA13+AG13+AM13 -> 921.86186 | AR13: =L13+R13+W13+AA13+AG13+AM13 -> 1310.1819
B14: Dallas
B15: Houston
B16: BRZ | M16: =EXPORT!O8 -> 0 | R16: =EXPORT!Z8 -> 0 | W16: =EXPORT!AK8 -> 0 | AA16: =EXPORT!AV8 -> 70.942575 | AG16: =EXPORT!BG8 -> 77.5752 | AM16: =EXPORT!BR8 -> 199.79452 | AQ16: =M16+R16+W16+AA16+AG16+AM16 -> 348.3123
B17: AUS
C19: Origin Warehouse | N19: Inland Logistics | S19: Consolidation | X19: Outbound Logistics | AB19: Documentation | AH19: CIF | AN19: Cert Costs | AQ19: Terms Total
C20: Terms | D20: Receiving | E20: Load Out | F20: Compression | G20: Class | H20: Marking | I20: Storage | J20: Interest | K20: Origin Commission | L20: Total Equity | M20: Total Origin | N20: Flatbed | O20: Late Loading | P20: Transit Truck | R20: Total Inland | S20: Block Handling | T20: Storage | U20: Interest | W20: Total Consol | X20: Dray | Y20: Ocean | AA20: Total Out | AB20: Sight LC | AC20: Forwarding | AD20: Controlling | AE20: Insurance | AG20: Total Doc | AH20: Destination Comission | AI20: Cost of Funds | AJ20: Qclaim | AK20: Interest | AM20: Total CIF | AN20: USDA | AO20: ICE | AP20: Total CERT | AQ20: Cash | AR20: Equity
B21: WTX-Dallas Cert-Block Out | F21: =$F$5 -> 203.04912 | I21: =I5 -> 54.473684 | J21: =J5 -> 37.916667 | M21: =M5 -> 307.52024 | N21: =N5 -> 4.9122807 | O21: =O5 -> 1.1403509 | P21: =P5 -> 186.05615 | R21: =R5 -> 192.33066 | S21: =S5 -> 54 | W21: =S21+T21+U21+V21 -> 54 | AN21: =COSTS!$X$17 -> 85 | AO21: =COSTS!$X$18 -> 40 | AP21: =AN21+AO21 -> 125 | AQ21: =M21+R21+W21+AP21 -> 678.8509
B22: WTX-Dallas Cert-Break Out | F22: =$F$5 -> 203.04912 | I22: =I6 -> 53.622642 | J22: =J5 -> 37.916667 | M22: =M5 -> 307.52024 | N22: =N5 -> 4.9122807 | O22: =O5 -> 1.1403509 | P22: =P5 -> 186.05615 | R22: =R5 -> 192.33066 | S22: =COSTS!X19 -> 127 | W22: =S22+T22+U22+V22 -> 127 | AN22: =COSTS!$X$17 -> 85 | AO22: =COSTS!$X$18 -> 40 | AP22: =AN22+AO22 -> 125 | AQ22: =M22+R22+W22+AP22 -> 751.8509
B23: WTX-Houston Cert-Block Out | F23: =$F$5 -> 203.04912 | I23: =$I$5 -> 54.473684 | J23: =J5 -> 37.916667 | M23: =M5 -> 307.52024 | N23: =N5 -> 4.9122807 | O23: =O5 -> 1.1403509 | P23: =P6 -> 288.72326 | R23: =R6 -> 294.60561 | S23: =S7 -> 54 | W23: =S23+T23+U23+V23 -> 54 | AN23: =COSTS!$X$17 -> 85 | AO23: =COSTS!$X$18 -> 40 | AP23: =AN23+AO23 -> 125 | AQ23: =M23+R23+W23+AP23 -> 781.12585
B24: WTX- Houston Cert-Break Out | F24: =$F$5 -> 203.04912 | I24: =$I$5 -> 54.473684 | J24: =J5 -> 37.916667 | M24: =M5 -> 307.52024 | N24: =N5 -> 4.9122807 | O24: =O5 -> 1.1403509 | P24: =P6 -> 288.72326 | R24: =R6 -> 294.60561 | S24: =COSTS!X19 -> 127 | W24: =S24+T24+U24+V24 -> 127 | AN24: =COSTS!$X$17 -> 85 | AO24: =COSTS!$X$18 -> 40 | AP24: =AN24+AO24 -> 125 | AQ24: =M24+R24+W24+AP24 -> 854.12585
B25: STX-Houston Cert-Block Out | E25: =E7 -> 203.10345 | F25: =F7 -> 136.96552 | G25: =G12 -> 2.0689655 | I25: =I7 -> 76.586207 | J25: =J7 -> 37.916667 | M25: =M7 -> 452.33046 | N25: =N7 -> 4.8275862 | O25: =O7 -> 0 | P25: =P7 -> 200.75758 | R25: =R7 -> 205.94276 | S25: =S7 -> 54 | W25: =S25+T25+U25+V25 -> 54 | AN25: =COSTS!$X$17 -> 85 | AO25: =COSTS!$X$18 -> 40 | AP25: =AN25+AO25 -> 125 | AQ25: =M25+R25+W25+AP25 -> 837.27322
B26: STX-Houston Cert-Break Out | E26: =E7 -> 203.10345 | F26: =F7 -> 136.96552 | G26: =G12 -> 2.0689655 | I26: =I7 -> 76.586207 | J26: =J7 -> 37.916667 | M26: =M7 -> 452.33046 | N26: =N7 -> 4.8275862 | O26: =O7 -> 0 | P26: =P7 -> 200.75758 | R26: =R7 -> 205.94276 | S26: =COSTS!X19 -> 127 | W26: =S26+T26+U26+V26 -> 127 | AN26: =COSTS!$X$17 -> 85 | AO26: =COSTS!$X$18 -> 40 | AP26: =AN26+AO26 -> 125 | AQ26: =M26+R26+W26+AP26 -> 910.27322
B27: ME-Memphis Cert-Block Out | I27: =I8 -> 68.733333 | J27: =J8 -> 37.916667 | M27: =M8 -> 106.65 | N27: =N8 -> 0.26666667 | O27: =O8 -> 0.73333333 | P27: =P8 -> 211.56873 | R27: =R13 -> 212.56873 | S27: =S8 -> 50.48 | W27: =S27+T27+U27+V27 -> 50.48 | AN27: =COSTS!$X$17 -> 85 | AO27: =COSTS!$X$18 -> 40 | AP27: =AN27+AO27 -> 125 | AQ27: =M27+R27+W27+AP27 -> 494.69873
B28: ME-Memphis Cert-Break Out | I28: =I8 -> 68.733333 | J28: =J8 -> 37.916667 | M28: =M8 -> 106.65 | N28: =N8 -> 0.26666667 | O28: =O8 -> 0.73333333 | P28: =P8 -> 211.56873 | R28: =R13 -> 212.56873 | S28: =COSTS!X19 -> 127 | W28: =S28+T28+U28+V28 -> 127 | AN28: =COSTS!$X$17 -> 85 | AO28: =COSTS!$X$18 -> 40 | AP28: =AN28+AO28 -> 125 | AQ28: =M28+R28+W28+AP28 -> 571.21873
B29: Savannah | I29: =I9 -> 57.318841 | J29: =J9 -> 37.916667 | M29: =M9 -> 41.307971 | N29: =N9 -> 0 | O29: =O9 -> 0.82345191 | P29: =P9 -> 203.95335 | R29: =R9 -> 204.78891 | S29: =S9 -> 52 | W29: =S29+T29+U29+V29 -> 52 | AN29: =COSTS!$X$17 -> 85 | AO29: =COSTS!$X$18 -> 40 | AP29: =AN29+AO29 -> 125 | AQ29: =M29+R29+W29+AP29 -> 423.09688
B30: Savannah | I30: =I9 -> 57.318841 | J30: =J9 -> 37.916667 | M30: =M9 -> 41.307971 | N30: =N9 -> 0 | O30: =O9 -> 0.82345191 | P30: =P9 -> 203.95335 | R30: =R9 -> 204.78891 | S30: =COSTS!X19 -> 127 | W30: =S30+T30+U30+V30 -> 127 | AN30: =COSTS!$X$17 -> 85 | AO30: =COSTS!$X$18 -> 40 | AP30: =AN30+AO30 -> 125 | AQ30: =M30+R30+W30+AP30 -> 498.09688
T33: *1 MONTHS OF STORAGE
C34: Origin Warehouse | N34: Inland Logistics | S34: Cert Storage Costs | X34: Outbound Logistics | AB34: Documentation | AH34: CIF | AN34: Cert Costs | AQ34: Terms Total
C35: Terms | D35: Receiving | E35: Load Out | F35: Compression | G35: Class | H35: Marking | I35: Storage | J35: Interest | K35: Origin Commission | L35: Total Equity | M35: Total Origin | N35: Flatbed | O35: Late Loading | P35: Transit Truck | R35: Total Inland | S35: Storage | T35: Interest | U35: Interest | W35: Total Cert | X35: Dray | Y35: Ocean | AA35: Total Out | AB35: Sight LC | AC35: Forwarding | AD35: Controlling | AE35: Insurance | AG35: Total Doc | AH35: Destination Comission | AI35: Cost of Funds | AJ35: Qclaim | AM35: Total CIF | AN35: USDA | AO35: ICE | AP35: Total CERT | AQ35: Cash | AR35: Equity
B36: Memphis Stop | S36: ='Cert Tariffs'!H3 -> 90.3125 | T36: ='Cert Tariffs'!I3 -> 40.625 | W36: =S36+T36+U36+V36 -> 130.9375 | X36: =X8 -> 144.45455 | Y36: =Y8 -> 182.72727 | AA36: =X36+Y36+Z36 -> 327.18182 | AB36: =AB8 -> 28.8143 | AC36: =AC8 -> 6.9731405 | AD36: =AD8 -> 12.587317 | AE36: =AE8 -> 6.7352 | AG36: =AB36+AC36+AD36+AE36+AF36 -> 55.109958 | AH36: =AH8 -> 80 | AI36: =AI8 -> 26.178082 | AJ36: =AJ8 -> 0 | AK36: =AK8 -> 0 | AM36: =AH36+AI36+AJ36+AK36+AL36 -> 106.17808 | AQ36: =W36+AA36+AG36+AM36 -> 619.40736
B37: Houston Stop | S37: ='Cert Tariffs'!M3 -> 97 | T37: ='Cert Tariffs'!N3 -> 40.625 | W37: =S37+T37+U37+V37 -> 137.625 | X37: =X7 -> 133.97335 | Y37: =Y6 -> 197.95455 | AA37: =X37+Y37+Z37 -> 331.9279 | AB37: =AB7 -> 28.8143 | AC37: =AC7 -> 6.9731405 | AD37: =AD7 -> 12.587317 | AE37: =AE7 -> 6.7352 | AG37: =AB37+AC37+AD37+AE37+AF37 -> 55.109958 | AH37: =AH7 -> 80 | AI37: =AI7 -> 26.178082 | AJ37: =AJ7 -> 0 | AK37: =AK7 -> 0 | AM37: =AH37+AI37+AJ37+AK37+AL37 -> 106.17808 | AQ37: =W37+AA37+AG37+AM37 -> 630.84094
B38: Dallas Stop | S38: ='Cert Tariffs'!R3 -> 100.6 | T38: ='Cert Tariffs'!S3 -> 40.625 | W38: =S38+T38+U38+V38 -> 141.225 | X38: =X5 -> 162.5 | Y38: =Y5 -> 268.18182 | AA38: =X38+Y38+Z38 -> 430.68182 | AB38: =AB5 -> 28.8143 | AC38: =AC5 -> 6.9731405 | AD38: =AD5 -> 12.587317 | AE38: =AE5 -> 6.7352 | AG38: =AB38+AC38+AD38+AE38+AF38 -> 55.109958 | AH38: =AH5 -> 80 | AI38: =AI5 -> 26.178082 | AJ38: =AJ5 -> 0 | AK38: =AK5 -> 0 | AM38: =AH38+AI38+AJ38+AK38+AL38 -> 106.17808 | AQ38: =W38+AA38+AG38+AM38 -> 733.19486
B39: Savannah Stop | S39: ='Cert Tariffs'!W3 -> 110 | T39: ='Cert Tariffs'!X3 -> 40.625 | W39: =S39+T39+U39+V39 -> 150.625 | X39: =X9 -> 110.22727 | Y39: =Y9 -> 107.04545 | AA39: =X39+Y39+Z39 -> 217.27273 | AB39: =AB9 -> 28.8143 | AC39: =AC9 -> 6.9731405 | AD39: =AD9 -> 12.587317 | AE39: =AE9 -> 6.7352 | AG39: =AB39+AC39+AD39+AE39+AF39 -> 55.109958 | AH39: =AH9 -> 80 | AI39: =AI9 -> 26.178082 | AJ39: =AJ9 -> 0 | AK39: =AK9 -> 0 | AM39: =AH39+AI39+AJ39+AK39+AL39 -> 106.17808 | AQ39: =W39+AA39+AG39+AM39 -> 529.18577

Sheet EXPORT
F2: ---annual (season)--- | Q2: ---quartly--- | AB2: ---annual (season)--- | AM2: ---varible by origin and destination--- | AX2: ---varies by desination only--- | BI2: ---varies by desination & underlying price--- | BT2: ---total costings per destination--- | CE2: ---pnd base cif---
F3: Origin | Q3: Inland Logistics | AB3: Consolidation | AM3: Outbound Logistics | AX3: Documentation/Execution | BI3: CIF COSTS | BT3: TOTAL COSTINGS | CE3: PREIMIUM AND DISCOUNTS
F4: Receiving | G4: Load Out | H4: Compression | I4: Class | J4: Marking | K4: Storage | L4: Interest | M4: Origin Comm | Q4: Flatbed | R4: Late Fee | S4: Transit Truck | AB4: Block Handling | AC4: Storage | AD4: Interest | AM4: Dray | AN4: Ocean | AX4: Sight LC | AY4: Forwarding | AZ4: Controlling | BA4: Insurance | BI4: Dest Comission | BJ4: High Seas | BK4: Qclaim | BL4: Interest
AM5: Dallas | AN5: Houston | AO5: Houston | AP5: Memphis | AQ5: Savannah
C6: TT | D6: FT | F6: WTX | G6: WTXH | H6: STX | I6: MR5 | J6: ER5 | K6: EMOT | L6: ME | M6: HOU | N6: DAL | O6: BRZ | P6: AUS | Q6: WTX | R6: WTXH | S6: STX | T6: MR5 | U6: ER5 | V6: EMOT | W6: ME | X6: HOU | Y6: DAL | Z6: BRZ | AA6: AUS | AB6: WTX | AC6: WTXH | AD6: STX | AE6: MR5 | AF6: ER5 | AG6: EMOT | AH6: ME | AI6: HOU | AJ6: DAL | AK6: BRZ | AL6: AUS | AM6: WTX | AN6: WTXH | AO6: STX | AP6: MR5 | AQ6: ER5 | AR6: EMOT | AS6: ME | AT6: HOU | AU6: DAL | AV6: BRZ | AW6: AUS | AX6: WTX | AY6: WTXH | AZ6: STX | BA6: MR5 | BB6: ER5 | BC6: EMOT | BD6: ME | BE6: HOU | BF6: DAL | BG6: BRZ | BH6: AUS | BI6: WTX | BJ6: WTXH | BK6: STX | BL6: MR5 | BM6: ER5 | BN6: EMOT | BO6: ME | BP6: HOU | BQ6: DAL | BR6: BRZ | BS6: AUS | BT6: WTX | BU6: WTXH | BV6: STX | BW6: MR5 | BX6: ER5 | BY6: EMOT | BZ6: ME | CA6: HOU | CB6: DAL | CC6: BRZ | CD6: AUS | CE6: WTX | CF6: WTXH | CG6: STX | CH6: MR5 | CI6: ER5 | CJ6: EMOT | CK6: ME | CL6: HOU | CM6: DAL | CN6: BRZ | CO6: AUS
A7: Base | E7: CIF FE | F7: =CIF!M5 -> 307.52024 | G7: =CIF!M6 -> 308.68205 | H7: =CIF!M7 -> 452.33046 | I7: =CIF!M8 -> 106.65 | J7: =AVERAGE(CIF!M9,CIF!M10) -> 63.672813 | K7: =AVERAGE(CIF!M5,CIF!M7,CIF!M8,CIF!M9,CIF!M10) -> 198.76926 | L7: =AVERAGE(CIF!M8:M10) -> 77.998542 | Q7: =CIF!R5 -> 192.33066 | R7: =CIF!R6 -> 294.60561 | S7: =CIF!R7 -> 205.94276 | T7: =CIF!R8 -> 212.56873 | U7: =AVERAGE(CIF!R9,CIF!R10) -> 222.95739 | V7: =AVERAGE(CIF!R5,CIF!R7,CIF!R8,CIF!R9,CIF!R10) -> 211.35138 | W7: =AVERAGE(CIF!R9,CIF!R10,CIF!R8) -> 219.4945 | AB7: =CIF!W5 -> 130.65 | AC7: =CIF!W6 -> 130.65 | AD7: =CIF!W7 -> 130.65 | AE7: =CIF!W8 -> 112.346 | AF7: =AVERAGE(CIF!W9:W10) -> 127.7216 | AG7: =AVERAGE(CIF!W5,CIF!W7,CIF!W8,CIF!W9,CIF!W10) -> 125.81784 | AH7: =AVERAGE(CIF!W8,CIF!W9,CIF!W10) -> 122.5964 | AI7: =CIF!W15 -> 0 | AJ7: =CIF!W14 -> 0 | AM7: =CIF!$X$5+VLOOKUP($AM$5&$E7,OCEAN!$E:$J,5,FALSE) -> 430.68182 | AN7: =CIF!$X$6+VLOOKUP($AN$5&$E7,OCEAN!$E:$J,5,FALSE) -> 331.9279 | AO7: =CIF!$X$7+VLOOKUP($AO$5&$E7,OCEAN!$E:$J,5,FALSE) -> 331.9279 | AP7: =CIF!$X$8+VLOOKUP($AP$5&$E7,OCEAN!$E:$J,5,FALSE) -> 327.18182 | AQ7: =CIF!$X$9+VLOOKUP($AQ$5&$E7,OCEAN!$E:$J,5,FALSE) -> 217.27273 | AR7: =AVERAGE(AM7,AO7,AP7,AQ7) -> 326.76607 | AS7: =AVERAGE(AP7,AQ7) -> 272.22727 | AX7: =CIF!AG5 -> 55.109958 | AY7: =CIF!AG6 -> 55.109958 | AZ7: =CIF!AG7 -> 55.109958 | BA7: =CIF!AG8 -> 55.109958 | BB7: =CIF!AG9 -> 55.109958 | BC7: =AVERAGE(CIF!AG5,CIF!AG7,CIF!AG8,CIF!AG9,CIF!AG10) -> 55.109958 | BD7: =AVERAGE(CIF!AG8:AG10) -> 55.109958 | BI7: =CIF!$AM5 -> 106.17808 | BJ7: =CIF!$AM6 -> 106.17808 | BK7: =CIF!$AM7 -> 106.17808 | BL7: =CIF!$AM8 -> 106.17808 | BM7: =CIF!$AM9 -> 106.17808 | BN7: =AVERAGE(CIF!AM5,CIF!AM7,CIF!AM8,CIF!AM9,CIF!AM10) -> 106.17808 | BO7: =AVERAGE(CIF!AM8:AM10) -> 106.17808 | BP7: =CIF!AM15 -> 0 | BQ7: =CIF!AM14 -> 0 | BT7: =CIF!AQ5 -> 1222.4708 | BU7: =CIF!$AQ6 -> 1226.1348 | BV7: =CIF!$AQ7 -> 1284.5608 | BW7: =CIF!$AQ8 -> 921.60277 | BX7: =J7+U7+AF7+AQ7+BB7+BM7 -> 792.91257 | BY7: =K7+V7+AG7+AR7+BC7+BN7 -> 1023.9926 | BZ7: =L7+W7+AH7+AS7+BD7+BO7 -> 853.60476 | CC7: 348 | CD7: 284 | CE7: =BT7-CIF!AQ5 -> 0 | CF7: =BU7-CIF!AQ6 -> 0 | CG7: =BV7-CIF!AQ7 -> 0 | CH7: =BW7-CIF!AQ8 -> 0 | CI7: 0 | CJ7: 0 | CK7: 0 | CL7: 0 | CM7: 0
A8: China | B8: CN | C8: 38 | D8: 18 | E8: Qingdao | F8: =$F$7 -> 307.52024 | G8: =$G$7 -> 308.68205 | H8: =$H$7 -> 452.33046 | I8: =$I$7 -> 106.65 | J8: =$J$7 -> 63.672813 | K8: =$K$7 -> 198.76926 | L8: =$L$7 -> 77.998542 | Q8: =$Q$7 -> 192.33066 | R8: =$R$7 -> 294.60561 | S8: =$S$7 -> 205.94276 | T8: =$T$7 -> 212.56873 | U8: =$U$7 -> 222.95739 | V8: =$V$7 -> 211.35138 | W8: =$W$7 -> 219.4945 | AB8: =$AB$7 -> 130.65 | AC8: =$AC$7 -> 130.65 | AD8: =$AD$7 -> 130.65 | AE8: =$AE$7 -> 112.346 | AF8: =$AF$7 -> 127.7216 | AG8: =$AG$7 -> 125.81784 | AH8: =$AH$7 -> 122.5964 | AI8: =$AI$7 -> 0 | AJ8: =$AJ$7 -> 0 | AM8: =CIF!$X$5+VLOOKUP($AM$5&$E8,OCEAN!$E:$J,5,FALSE) -> 430.68182 | AN8: =CIF!$X$6+VLOOKUP($AN$5&$E8,OCEAN!$E:$J,5,FALSE) -> 331.9279 | AO8: =CIF!$X$7+VLOOKUP($AO$5&$E8,OCEAN!$E:$J,5,FALSE) -> 331.9279 | AP8: =CIF!$X$8+VLOOKUP($AP$5&$E8,OCEAN!$E:$J,5,FALSE) -> 327.18182 | AQ8: =CIF!$X$9+VLOOKUP($AQ$5&$E8,OCEAN!$E:$J,5,FALSE) -> 217.27273 | AR8: =AVERAGE(IF(ISNUMBER(AM8),AM8,""),IF(ISNUMBER(AO8),AO8,""),IF(ISNUMBER(AP8),AP8,""),IF(ISNUMBER(AQ8),AQ8,"")) -> 326.76607 | AS8: =AVERAGE(IF(ISNUMBER(AP8),AP8,""),IF(ISNUMBER(AQ8),AQ8,"")) -> 272.22727 | AV8: =CIF!$X$16+VLOOKUP($AV$6&$E8,OCEAN!$E:$J,5,FALSE) -> 70.942575 | AW8: =CIF!$X$17+VLOOKUP($AW$6&$E8,OCEAN!$E:$J,5,FALSE) -> 35.924884 | AX8: =$AX$7 -> 55.109958 | AY8: =$AY$7 -> 55.109958 | AZ8: =$AY$8 -> 55.109958 | BA8: =$BA$7 -> 55.109958 | BB8: =$BB$7 -> 55.109958 | BC8: =$BB$7 -> 55.109958 | BD8: =$BB$7 -> 55.109958 | BE8: =$BB$7 -> 55.109958 | BF8: =$BB$7 -> 55.109958 | BG8: =COSTS!I5+COSTS!J5+COSTS!K5 -> 77.5752 | BH8: =COSTS!O5+COSTS!P5+COSTS!Q5 -> 48.0888 | BI8: =COSTS!F5+COSTS!G5+COSTS!H5 -> 106.17808 | BJ8: =COSTS!F5+COSTS!G5+COSTS!H5 -> 106.17808 | BK8: =COSTS!F5+COSTS!G5+COSTS!H5 -> 106.17808 | BL8: =COSTS!F5+COSTS!G5+COSTS!H5 -> 106.17808 | BM8: =COSTS!F5+COSTS!G5+COSTS!H5 -> 106.17808 | BN8: =COSTS!F5+COSTS!G5+COSTS!H5 -> 106.17808 | BO8: =COSTS!F5+COSTS!G5+COSTS!H5 -> 106.17808 | BP8: =COSTS!F5+COSTS!G5+COSTS!H5 -> 106.17808 | BQ8: =COSTS!F5+COSTS!G5+COSTS!H5 -> 106.17808 | BR8: =COSTS!L5+COSTS!M5+COSTS!N5 -> 199.79452 | BS8: =COSTS!R5+COSTS!S5+COSTS!T5 -> 199 | BT8: =F8+Q8+AB8+AM8+AX8+BI8 -> 1222.4708 | BU8: =G8+R8+AC8+AN8+AY8+BJ8 -> 1227.1536 | BV8: =H8+S8+AD8+AO8+AZ8+BK8 -> 1282.1392 | BW8: =I8+T8+AE8+AP8+BA8+BL8 -> 920.03459 | BX8: =J8+U8+AF8+AQ8+BB8+BM8 -> 792.91257 | BY8: =K8+V8+AG8+AR8+BC8+BN8 -> 1023.9926 | BZ8: =L8+W8+AH8+AS8+BD8+BO8 -> 853.60476 | CA8: =M8+X8+AI8+AT8+BE8+BP8 -> 161.28804 | ... CD8: =P8+AA8+AL8+AW8+BH8+BS8 -> 283.01368 | CE8: =BT8-$BT$7 -> 0 | CF8: =BU8-$BU$7 -> 1.0188088 | CG8: =BV8-$BV$7 -> -2.4216301 | CH8: =BW8-$BW$7 -> -1.5681818 | CI8: =BX8-$BX$7 -> 0 | CJ8: =BY8-$BY$7 -> 0 | CK8: =BZ8-$BZ$7 -> 0 | CN8: =CC8-$CC$7 -> 0.31229516 | CO8: =CD8-$CD$7 -> -0.98631567
E9: Xiamen | F9: =$F$7 -> 307.52024 | G9: =$G$7 -> 308.68205 | H9: =$H$7 -> 452.33046 | I9: =$I$7 -> 106.65 | J9: =$J$7 -> 63.672813 | K9: =$K$7 -> 198.76926 | L9: =$L$7 -> 77.998542 | Q9: =$Q$7 -> 192.33066 | R9: =$R$7 -> 294.60561 | S9: =$S$7 -> 205.94276 | T9: =$T$7 -> 212.56873 | U9: =$U$7 -> 222.95739 | V9: =$V$7 -> 211.35138 | W9: =$W$7 -> 219.4945 | AB9: =$AB$7 -> 130.65 | AC9: =$AC$7 -> 130.65 | AD9: =$AD$7 -> 130.65 | AE9: =$AE$7 -> 112.346 | AF9: =$AF$7 -> 127.7216 | AG9: =$AG$7 -> 125.81784 | AH9: =$AH$7 -> 122.5964 | AI9: =$AI$7 -> 0 | AJ9: =$AJ$7 -> 0 | AM9: =CIF!$X$5+VLOOKUP($AM$5&$E9,OCEAN!$E:$J,5,FALSE) -> 378.40909 | AN9: =CIF!$X$6+VLOOKUP($AN$5&$E9,OCEAN!$E:$J,5,FALSE) -> 304.4279 | AO9: =CIF!$X$7+VLOOKUP($AO$5&$E9,OCEAN!$E:$J,5,FALSE) -> 304.4279 | AP9: =CIF!$X$8+VLOOKUP($AP$5&$E9,OCEAN!$E:$J,5,FALSE) -> 292.18182 | AQ9: =CIF!$X$9+VLOOKUP($AQ$5&$E9,OCEAN!$E:$J,5,FALSE) -> 258.18182 | AR9: =AVERAGE(IF(ISNUMBER(AM9),AM9,""),IF(ISNUMBER(AO9),AO9,""),IF(ISNUMBER(AP9),AP9,""),IF(ISNUMBER(AQ9),AQ9,"")) -> 308.30016 | AS9: =AVERAGE(IF(ISNUMBER(AP9),AP9,""),IF(ISNUMBER(AQ9),AQ9,"")) -> 275.18182 | AV9: =CIF!$X$16+VLOOKUP($AV$6&$E9,OCEAN!$E:$J,5,FALSE) -> 153.31579 | AW9: =CIF!$X$17+VLOOKUP($AW$6&$E9,OCEAN!$E:$J,5,FALSE) -> 63.866461 | AX9: =$AX$7 -> 55.109958 | AY9: =$AY$7 -> 55.109958 | AZ9: =$AY$8 -> 55.109958 | BA9: =$BA$7 -> 55.109958 | BB9: =$BB$7 -> 55.109958 | BC9: =$BB$7 -> 55.109958 | BD9: =$BB$7 -> 55.109958 | BE9: =$BB$7 -> 55.109958 | BF9: =$BB$7 -> 55.109958 | BG9: =COSTS!I5+COSTS!J5+COSTS!K5 -> 77.5752 | BH9: =COSTS!O5+COSTS!P5+COSTS!Q5 -> 48.0888 | BI9: =COSTS!F5+COSTS!G5+COSTS!H5 -> 106.17808 | BJ9: =COSTS!F5+COSTS!G5+COSTS!H5 -> 106.17808 | BK9: =COSTS!F5+COSTS!G5+COSTS!H5 -> 106.17808 | BL9: =COSTS!F5+COSTS!G5+COSTS!H5 -> 106.17808 | BM9: =COSTS!F5+COSTS!G5+COSTS!H5 -> 106.17808 | BN9: =COSTS!F5+COSTS!G5+COSTS!H5 -> 106.17808 | BO9: =COSTS!F5+COSTS!G5+COSTS!H5 -> 106.17808 | BP9: =COSTS!F5+COSTS!G5+COSTS!H5 -> 106.17808 | BQ9: =COSTS!F5+COSTS!G5+COSTS!H5 -> 106.17808 | BR9: =COSTS!L5+COSTS!M5+COSTS!N5 -> 199.79452 | BS9: =COSTS!R5+COSTS!S5+COSTS!T5 -> 199 | BT9: =F9+Q9+AB9+AM9+AX9+BI9 -> 1170.198 | BU9: =G9+R9+AC9+AN9+AY9+BJ9 -> 1199.6536 | BV9: =H9+S9+AD9+AO9+AZ9+BK9 -> 1254.6392 | BW9: =I9+T9+AE9+AP9+BA9+BL9 -> 885.03459 | BX9: =J9+U9+AF9+AQ9+BB9+BM9 -> 833.82166 | BY9: =K9+V9+AG9+AR9+BC9+BN9 -> 1005.5267 | BZ9: =L9+W9+AH9+AS9+BD9+BO9 -> 856.5593 | CA9: =M9+X9+AI9+AT9+BE9+BP9 -> 161.28804 | ... CD9: =P9+AA9+AL9+AW9+BH9+BS9 -> 310.95526 | CE9: =BT9-$BT$7 -> -52.272727 | CF9: =BU9-$BU$7 -> -26.481191 | CG9: =BV9-$BV$7 -> -29.92163 | CH9: =BW9-$BW$7 -> -36.568182 | CI9: =BX9-$BX$7 -> 40.909091 | CJ9: =BY9-$BY$7 -> -18.465909 | CK9: =BZ9-$BZ$7 -> 2.9545455 | CN9: =CC9-$CC$7 -> 82.685515 | CO9: =CD9-$CD$7 -> 26.955261
E10: Lianyungang | F10: =$F$7 -> 307.52024 | G10: =$G$7 -> 308.68205 | H10: =$H$7 -> 452.33046 | I10: =$I$7 -> 106.65 | J10: =$J$7 -> 63.672813 | K10: =$K$7 -> 198.76926 | L10: =$L$7 -> 77.998542 | Q10: =$Q$7 -> 192.33066 | R10: =$R$7 -> 294.60561 | S10: =$S$7 -> 205.94276 | T10: =$T$7 -> 212.56873 | U10: =$U$7 -> 222.95739 | V10: =$V$7 -> 211.35138 | W10: =$W$7 -> 219.4945 | AB10: =$AB$7 -> 130.65 | AC10: =$AC$7 -> 130.65 | AD10: =$AD$7 -> 130.65 | AE10: =$AE$7 -> 112.346 | AF10: =$AF$7 -> 127.7216 | AG10: =$AG$7 -> 125.81784 | AH10: =$AH$7 -> 122.5964 | AI10: =$AI$7 -> 0 | AJ10: =$AJ$7 -> 0 | AM10: =CIF!$X$5+VLOOKUP($AM$5&$E10,OCEAN!$E:$J,5,FALSE) -> 560.22727 | AN10: =CIF!$X$6+VLOOKUP($AN$5&$E10,OCEAN!$E:$J,5,FALSE) -> 338.74608 | AO10: =CIF!$X$7+VLOOKUP($AO$5&$E10,OCEAN!$E:$J,5,FALSE) -> 338.74608 | AP10: =CIF!$X$8+VLOOKUP($AP$5&$E10,OCEAN!$E:$J,5,FALSE) -> 401.27273 | AQ10: =CIF!$X$9+VLOOKUP($AQ$5&$E10,OCEAN!$E:$J,5,FALSE) -> 271.81818 | AR10: =AVERAGE(IF(ISNUMBER(AM10),AM10,""),IF(ISNUMBER(AO10),AO10,""),IF(ISNUMBER(AP10),AP10,""),IF(ISNUMBER(AQ10),AQ10,"")) -> 393.01607 | AS10: =AVERAGE(IF(ISNUMBER(AP10),AP10,""),IF(ISNUMBER(AQ10),AQ10,"")) -> 336.54545 | AV10: =CIF!$X$16+VLOOKUP($AV$6&$E10,OCEAN!$E:$J,5,FALSE) -> 143.5181 | AW10: =CIF!$X$17+VLOOKUP($AW$6&$E10,OCEAN!$E:$J,5,FALSE) -> #N/A | AX10: =$AX$7 -> 55.109958 | AY10: =$AY$7 -> 55.109958 | AZ10: =$AY$8 -> 55.109958 | BA10: =$BA$7 -> 55.109958 | BB10: =$BB$7 -> 55.109958 | BC10: =$BB$7 -> 55.109958 | BD10: =$BB$7 -> 55.109958 | BE10: =$BB$7 -> 55.109958 | BF10: =$BB$7 -> 55.109958 | BG10: =COSTS!I5+COSTS!J5+COSTS!K5 -> 77.5752 | BH10: =COSTS!O5+COSTS!P5+COSTS!Q5 -> 48.0888 | BI10: =COSTS!F5+COSTS!G5+COSTS!H5 -> 106.17808 | BJ10: =COSTS!F5+COSTS!G5+COSTS!H5 -> 106.17808 | BK10: =COSTS!F5+COSTS!G5+COSTS!H5 -> 106.17808 | BL10: =COSTS!F5+COSTS!G5+COSTS!H5 -> 106.17808 | BM10: =COSTS!F5+COSTS!G5+COSTS!H5 -> 106.17808 | BN10: =COSTS!F5+COSTS!G5+COSTS!H5 -> 106.17808 | BO10: =COSTS!F5+COSTS!G5+COSTS!H5 -> 106.17808 | BP10: =COSTS!F5+COSTS!G5+COSTS!H5 -> 106.17808 | BQ10: =COSTS!F5+COSTS!G5+COSTS!H5 -> 106.17808 | BR10: =COSTS!L5+COSTS!M5+COSTS!N5 -> 199.79452 | BS10: =COSTS!R5+COSTS!S5+COSTS!T5 -> 199 | BT10: =F10+Q10+AB10+AM10+AX10+BI10 -> 1352.0162 | BU10: =G10+R10+AC10+AN10+AY10+BJ10 -> 1233.9718 | BV10: =H10+S10+AD10+AO10+AZ10+BK10 -> 1288.9573 | BW10: =I10+T10+AE10+AP10+BA10+BL10 -> 994.12549 | BX10: =J10+U10+AF10+AQ10+BB10+BM10 -> 847.45802 | BY10: =K10+V10+AG10+AR10+BC10+BN10 -> 1090.2426 | BZ10: =L10+W10+AH10+AS10+BD10+BO10 -> 917.92294 | CA10: =M10+X10+AI10+AT10+BE10+BP10 -> 161.28804 | ... CD10: =P10+AA10+AL10+AW10+BH10+BS10 -> #N/A | CE10: =BT10-$BT$7 -> 129.54545 | CF10: =BU10-$BU$7 -> 7.8369906 | CG10: =BV10-$BV$7 -> 4.3965517 | CH10: =BW10-$BW$7 -> 72.522727 | CI10: =BX10-$BX$7 -> 54.545455 | CJ10: =BY10-$BY$7 -> 66.25 | CK10: =BZ10-$BZ$7 -> 64.318182 | CN10: =CC10-$CC$7 -> 72.887819 | CO10: =CD10-$CD$7 -> #N/A
A11: Vietnam | B11: VN | C11: 50 | D11: 14 | E11: Ho Chi Minh | F11: =$F$7 -> 307.52024 | G11: =$G$7 -> 308.68205 | H11: =$H$7 -> 452.33046 | I11: =$I$7 -> 106.65 | J11: =$J$7 -> 63.672813 | K11: =$K$7 -> 198.76926 | L11: =$L$7 -> 77.998542 | Q11: =$Q$7 -> 192.33066 | R11: =$R$7 -> 294.60561 | S11: =$S$7 -> 205.94276 | T11: =$T$7 -> 212.56873 | U11: =$U$7 -> 222.95739 | V11: =$V$7 -> 211.35138 | W11: =$W$7 -> 219.4945 | AB11: =$AB$7 -> 130.65 | AC11: =$AC$7 -> 130.65 | AD11: =$AD$7 -> 130.65 | AE11: =$AE$7 -> 112.346 | AF11: =$AF$7 -> 127.7216 | AG11: =$AG$7 -> 125.81784 | AH11: =$AH$7 -> 122.5964 | AI11: =$AI$7 -> 0 | AJ11: =$AJ$7 -> 0 | AM11: =CIF!$X$5+VLOOKUP($AM$5&$E11,OCEAN!$E:$J,5,FALSE) -> 449.31818 | AN11: =CIF!$X$6+VLOOKUP($AN$5&$E11,OCEAN!$E:$J,5,FALSE) -> 358.97335 | AO11: =CIF!$X$7+VLOOKUP($AO$5&$E11,OCEAN!$E:$J,5,FALSE) -> 358.97335 | AP11: =CIF!$X$8+VLOOKUP($AP$5&$E11,OCEAN!$E:$J,5,FALSE) -> 408.54545 | AQ11: =CIF!$X$9+VLOOKUP($AQ$5&$E11,OCEAN!$E:$J,5,FALSE) -> 256.81818 | AR11: =AVERAGE(IF(ISNUMBER(AM11),AM11,""),IF(ISNUMBER(AO11),AO11,""),IF(ISNUMBER(AP11),AP11,""),IF(ISNUMBER(AQ11),AQ11,"")) -> 368.41379 | AS11: =AVERAGE(IF(ISNUMBER(AP11),AP11,""),IF(ISNUMBER(AQ11),AQ11,"")) -> 332.68182 | AV11: =CIF!$X$16+VLOOKUP($AV$6&$E11,OCEAN!$E:$J,5,FALSE) -> 72.575524 | AW11: =CIF!$X$17+VLOOKUP($AW$6&$E11,OCEAN!$E:$J,5,FALSE) -> 90.900844 | AX11: =COSTS!C6+COSTS!D6+COSTS!E6 -> 67.416591 | AY11: =COSTS!C6+COSTS!D6+COSTS!E6 -> 67.416591 | AZ11: =COSTS!C6+COSTS!D6+COSTS!E6 -> 67.416591 | BA11: =COSTS!C6+COSTS!D6+COSTS!E6 -> 67.416591 | BB11: =COSTS!C6+COSTS!D6+COSTS!E6 -> 67.416591 | BC11: =COSTS!D6+COSTS!E6+COSTS!F6 -> 98.301924 | BD11: =COSTS!E6+COSTS!F6+COSTS!G6 -> 117.74481 | BE11: =COSTS!F6+COSTS!G6+COSTS!H6 -> 106.17808 | BF11: =COSTS!G6+COSTS!H6+COSTS!I6 -> 80.178082 | BG11: =COSTS!I6+COSTS!J6+COSTS!K6 -> 81 | BH11: =COSTS!O6+COSTS!P6+COSTS!Q6 -> 64.0888 | BI11: =COSTS!F6+COSTS!G6+COSTS!H6 -> 106.17808 | BJ11: =COSTS!F6+COSTS!G6+COSTS!H6 -> 106.17808 | BK11: =COSTS!F6+COSTS!G6+COSTS!H6 -> 106.17808 | BL11: =COSTS!F6+COSTS!G6+COSTS!H6 -> 106.17808 | BM11: =COSTS!F6+COSTS!G6+COSTS!H6 -> 106.17808 | BN11: =COSTS!F6+COSTS!G6+COSTS!H6 -> 106.17808 | BO11: =COSTS!F6+COSTS!G6+COSTS!H6 -> 106.17808 | BP11: =COSTS!F6+COSTS!G6+COSTS!H6 -> 106.17808 | BQ11: =COSTS!F6+COSTS!G6+COSTS!H6 -> 106.17808 | BR11: =COSTS!L6+COSTS!M6+COSTS!N6 -> 174.79452 | BS11: =COSTS!R6+COSTS!S6+COSTS!T6 -> 174 | BT11: =F11+Q11+AB11+AM11+AX11+BI11 -> 1253.4138 | BU11: =G11+R11+AC11+AN11+AY11+BJ11 -> 1266.5057 | BV11: =H11+S11+AD11+AO11+AZ11+BK11 -> 1321.4912 | BW11: =I11+T11+AE11+AP11+BA11+BL11 -> 1013.7049 | BX11: =J11+U11+AF11+AQ11+BB11+BM11 -> 844.76466 | BY11: =K11+V11+AG11+AR11+BC11+BN11 -> 1108.8323 | BZ11: =L11+W11+AH11+AS11+BD11+BO11 -> 976.69415 | CA11: =M11+X11+AI11+AT11+BE11+BP11 -> 212.35616 | ... CD11: =P11+AA11+AL11+AW11+BH11+BS11 -> 328.98964 | CE11: =BT11-$BT$7 -> 30.942997 | CF11: =BU11-$BU$7 -> 40.370896 | CG11: =BV11-$BV$7 -> 36.930457 | CH11: =BW11-$BW$7 -> 92.102087 | CI11: =BX11-$BX$7 -> 51.852087 | CJ11: =BY11-$BY$7 -> 84.839693 | CK11: =BZ11-$BZ$7 -> 123.08939 | CN11: =CC11-$CC$7 -> -19.629956 | CO11: =CD11-$CD$7 -> 44.989644
E12: DaNang | F12: =$F$7 -> 307.52024 | G12: =$G$7 -> 308.68205 | H12: =$H$7 -> 452.33046 | I12: =$I$7 -> 106.65 | J12: =$J$7 -> 63.672813 | K12: =$K$7 -> 198.76926 | L12: =$L$7 -> 77.998542 | Q12: =$Q$7 -> 192.33066 | R12: =$R$7 -> 294.60561 | S12: =$S$7 -> 205.94276 | T12: =$T$7 -> 212.56873 | U12: =$U$7 -> 222.95739 | V12: =$V$7 -> 211.35138 | W12: =$W$7 -> 219.4945 | AB12: =$AB$7 -> 130.65 | AC12: =$AC$7 -> 130.65 | AD12: =$AD$7 -> 130.65 | AE12: =$AE$7 -> 112.346 | AF12: =$AF$7 -> 127.7216 | AG12: =$AG$7 -> 125.81784 | AH12: =$AH$7 -> 122.5964 | AI12: =$AI$7 -> 0 | AJ12: =$AJ$7 -> 0 | AM12: =CIF!$X$5+VLOOKUP($AM$5&$E12,OCEAN!$E:$J,5,FALSE) -> 562.04545 | AN12: =CIF!$X$6+VLOOKUP($AN$5&$E12,OCEAN!$E:$J,5,FALSE) -> 435.79154 | AO12: =CIF!$X$7+VLOOKUP($AO$5&$E12,OCEAN!$E:$J,5,FALSE) -> 435.79154 | AP12: =CIF!$X$8+VLOOKUP($AP$5&$E12,OCEAN!$E:$J,5,FALSE) -> 489.90909 | AQ12: =CIF!$X$9+VLOOKUP($AQ$5&$E12,OCEAN!$E:$J,5,FALSE) -> 314.77273 | AR12: =AVERAGE(IF(ISNUMBER(AM12),AM12,""),IF(ISNUMBER(AO12),AO12,""),IF(ISNUMBER(AP12),AP12,""),IF(ISNUMBER(AQ12),AQ12,"")) -> 450.6297 | AS12: =AVERAGE(IF(ISNUMBER(AP12),AP12,""),IF(ISNUMBER(AQ12),AQ12,"")) -> 402.34091 | AV12: =CIF!$X$16+VLOOKUP($AV$6&$E12,OCEAN!$E:$J,5,FALSE) -> 36.287762 | AW12: =CIF!$X$17+VLOOKUP($AW$6&$E12,OCEAN!$E:$J,5,FALSE) -> 99.791345 | AX12: =COSTS!C6+COSTS!D6+COSTS!E6 -> 67.416591 | AY12: =COSTS!C6+COSTS!D6+COSTS!E6 -> 67.416591 | AZ12: =COSTS!C6+COSTS!D6+COSTS!E6 -> 67.416591 | BA12: =COSTS!C6+COSTS!D6+COSTS!E6 -> 67.416591 | BB12: =COSTS!C6+COSTS!D6+COSTS!E6 -> 67.416591 | BC12: =COSTS!D6+COSTS!E6+COSTS!F6 -> 98.301924 | BD12: =COSTS!E6+COSTS!F6+COSTS!G6 -> 117.74481 | BE12: =COSTS!F6+COSTS!G6+COSTS!H6 -> 106.17808 | BF12: =COSTS!G6+COSTS!H6+COSTS!I6 -> 80.178082 | BG12: =COSTS!I6+COSTS!J6+COSTS!K6 -> 81 | BH12: =COSTS!O6+COSTS!P6+COSTS!Q6 -> 64.0888 | BI12: =COSTS!F6+COSTS!G6+COSTS!H6 -> 106.17808 | BJ12: =COSTS!F6+COSTS!G6+COSTS!H6 -> 106.17808 | BK12: =COSTS!F6+COSTS!G6+COSTS!H6 -> 106.17808 | BL12: =COSTS!F6+COSTS!G6+COSTS!H6 -> 106.17808 | BM12: =COSTS!F6+COSTS!G6+COSTS!H6 -> 106.17808 | BN12: =COSTS!F6+COSTS!G6+COSTS!H6 -> 106.17808 | BO12: =COSTS!F6+COSTS!G6+COSTS!H6 -> 106.17808 | BP12: =COSTS!F6+COSTS!G6+COSTS!H6 -> 106.17808 | BQ12: =COSTS!F6+COSTS!G6+COSTS!H6 -> 106.17808 | BR12: =COSTS!L6+COSTS!M6+COSTS!N6 -> 174.79452 | BS12: =COSTS!R6+COSTS!S6+COSTS!T6 -> 174 | BT12: =F12+Q12+AB12+AM12+AX12+BI12 -> 1366.141 | BU12: =G12+R12+AC12+AN12+AY12+BJ12 -> 1343.3239 | BV12: =H12+S12+AD12+AO12+AZ12+BK12 -> 1398.3094 | BW12: =I12+T12+AE12+AP12+BA12+BL12 -> 1095.0685 | BX12: =J12+U12+AF12+AQ12+BB12+BM12 -> 902.7192 | BY12: =K12+V12+AG12+AR12+BC12+BN12 -> 1191.0482 | BZ12: =L12+W12+AH12+AS12+BD12+BO12 -> 1046.3532 | CA12: =M12+X12+AI12+AT12+BE12+BP12 -> 212.35616 | ... CD12: =P12+AA12+AL12+AW12+BH12+BS12 -> 337.88015 | CE12: =BT12-$BT$7 -> 143.67027 | CF12: =BU12-$BU$7 -> 117.18908 | CG12: =BV12-$BV$7 -> 113.74864 | CH12: =BW12-$BW$7 -> 173.46572 | CI12: =BX12-$BX$7 -> 109.80663 | CJ12: =BY12-$BY$7 -> 167.0556 | CK12: =BZ12-$BZ$7 -> 192.74848 | CN12: =CC12-$CC$7 -> -55.917717 | CO12: =CD12-$CD$7 -> 53.880145
E13: Haiphong | F13: =$F$7 -> 307.52024 | G13: =$G$7 -> 308.68205 | H13: =$H$7 -> 452.33046 | I13: =$I$7 -> 106.65 | J13: =$J$7 -> 63.672813 | K13: =$K$7 -> 198.76926 | L13: =$L$7 -> 77.998542 | Q13: =$Q$7 -> 192.33066 | R13: =$R$7 -> 294.60561 | S13: =$S$7 -> 205.94276 | T13: =$T$7 -> 212.56873 | U13: =$U$7 -> 222.95739 | V13: =$V$7 -> 211.35138 | W13: =$W$7 -> 219.4945 | AB13: =$AB$7 -> 130.65 | AC13: =$AC$7 -> 130.65 | AD13: =$AD$7 -> 130.65 | AE13: =$AE$7 -> 112.346 | AF13: =$AF$7 -> 127.7216 | AG13: =$AG$7 -> 125.81784 | AH13: =$AH$7 -> 122.5964 | AI13: =$AI$7 -> 0 | AJ13: =$AJ$7 -> 0 | AM13: =CIF!$X$5+VLOOKUP($AM$5&$E13,OCEAN!$E:$J,5,FALSE) -> 443.63636 | AN13: =CIF!$X$6+VLOOKUP($AN$5&$E13,OCEAN!$E:$J,5,FALSE) -> 344.88245 | AO13: =CIF!$X$7+VLOOKUP($AO$5&$E13,OCEAN!$E:$J,5,FALSE) -> 344.88245 | AP13: =CIF!$X$8+VLOOKUP($AP$5&$E13,OCEAN!$E:$J,5,FALSE) -> 402.63636 | AQ13: =CIF!$X$9+VLOOKUP($AQ$5&$E13,OCEAN!$E:$J,5,FALSE) -> 254.77273 | AR13: =AVERAGE(IF(ISNUMBER(AM13),AM13,""),IF(ISNUMBER(AO13),AO13,""),IF(ISNUMBER(AP13),AP13,""),IF(ISNUMBER(AQ13),AQ13,"")) -> 361.48197 | AS13: =AVERAGE(IF(ISNUMBER(AP13),AP13,""),IF(ISNUMBER(AQ13),AQ13,"")) -> 328.70455 | AV13: =CIF!$X$16+VLOOKUP($AV$6&$E13,OCEAN!$E:$J,5,FALSE) -> 72.575524 | AW13: =CIF!$X$17+VLOOKUP($AW$6&$E13,OCEAN!$E:$J,5,FALSE) -> 90.900844 | AX13: =COSTS!C6+COSTS!D6+COSTS!E6 -> 67.416591 | AY13: =COSTS!C6+COSTS!D6+COSTS!E6 -> 67.416591 | AZ13: =COSTS!C6+COSTS!D6+COSTS!E6 -> 67.416591 | BA13: =COSTS!C6+COSTS!D6+COSTS!E6 -> 67.416591 | BB13: =COSTS!C6+COSTS!D6+COSTS!E6 -> 67.416591 | BC13: =COSTS!D6+COSTS!E6+COSTS!F6 -> 98.301924 | BD13: =COSTS!E6+COSTS!F6+COSTS!G6 -> 117.74481 | BE13: =COSTS!F6+COSTS!G6+COSTS!H6 -> 106.17808 | BF13: =COSTS!G6+COSTS!H6+COSTS!I6 -> 80.178082 | BG13: =COSTS!I6+COSTS!J6+COSTS!K6 -> 81 | BH13: =COSTS!O6+COSTS!P6+COSTS!Q6 -> 64.0888 | BI13: =COSTS!F6+COSTS!G6+COSTS!H6 -> 106.17808 | BJ13: =COSTS!F6+COSTS!G6+COSTS!H6 -> 106.17808 | BK13: =COSTS!F6+COSTS!G6+COSTS!H6 -> 106.17808 | BL13: =COSTS!F6+COSTS!G6+COSTS!H6 -> 106.17808 | BM13: =COSTS!F6+COSTS!G6+COSTS!H6 -> 106.17808 | BN13: =COSTS!F6+COSTS!G6+COSTS!H6 -> 106.17808 | BO13: =COSTS!F6+COSTS!G6+COSTS!H6 -> 106.17808 | BP13: =COSTS!F6+COSTS!G6+COSTS!H6 -> 106.17808 | BQ13: =COSTS!F6+COSTS!G6+COSTS!H6 -> 106.17808 | BR13: =COSTS!L6+COSTS!M6+COSTS!N6 -> 174.79452 | BS13: =COSTS!R6+COSTS!S6+COSTS!T6 -> 174 | BT13: =F13+Q13+AB13+AM13+AX13+BI13 -> 1247.7319 | BU13: =G13+R13+AC13+AN13+AY13+BJ13 -> 1252.4148 | BV13: =H13+S13+AD13+AO13+AZ13+BK13 -> 1307.4003 | BW13: =I13+T13+AE13+AP13+BA13+BL13 -> 1007.7958 | BX13: =J13+U13+AF13+AQ13+BB13+BM13 -> 842.7192 | BY13: =K13+V13+AG13+AR13+BC13+BN13 -> 1101.9005 | BZ13: =L13+W13+AH13+AS13+BD13+BO13 -> 972.71688 | CA13: =M13+X13+AI13+AT13+BE13+BP13 -> 212.35616 | ... CD13: =P13+AA13+AL13+AW13+BH13+BS13 -> 328.98964 | CE13: =BT13-$BT$7 -> 25.261178 | CF13: =BU13-$BU$7 -> 26.279987 | CG13: =BV13-$BV$7 -> 22.839548 | CH13: =BW13-$BW$7 -> 86.192997 | CI13: =BX13-$BX$7 -> 49.806633 | CJ13: =BY13-$BY$7 -> 77.907875 | CK13: =BZ13-$BZ$7 -> 119.11212 | CN13: =CC13-$CC$7 -> -19.629956 | CO13: =CD13-$CD$7 -> 44.989644
